Workbook

Sheet 이베이
A1: 머레이 이베이 월별 매출정리
A2: 날짜 | B2: 총광고비용 | C2: 전환수 | D2: 광고센터 전환매출 | E2: 광고센터 ROAS | F2: 실매출 판매금액 | G2: 실매출 취소금액 | H2: 실매출 합계 | I2: 실매출 ROAS
A3: 합계 | B3: =sum(B4:B33) -> 3189736 | C3: =sum(C4:C33) -> 435 | D3: =sum(D4:D33) -> 26271600 | E3: =iferror(D3/B3,0) -> 8.2362929 | F3: =sum(F4:F33) -> 38761400 | G3: =sum(G4:G33) -> 3674800 | H3: =sum(H4:H33) -> 35086600 | I3: =iferror(H3/B3,0) -> 10.999845
A4: 45962 | B4: =sum(sumifs('파워클릭 raw'!$G:$G,'파워클릭 raw'!$A:$A,$A4),sumifs('Ai매출업 raw'!$D:$D,'Ai매출업 raw'!$A:$A,$A4)) -> 150953 | C4: =sum(sumifs('파워클릭 raw'!$H:$H,'파워클릭 raw'!$A:$A,$A4),sumifs('Ai매출업 raw'!$I:$I,'Ai매출업 raw'!$A:$A,$A4)) -> 24 | D4: =sum(sumifs('파워클릭 raw'!$I:$I,'파워클릭 raw'!$A:$A,$A4),sumifs('Ai매출업 raw'!$J:$J,'Ai매출업 raw'!$A:$A,$A4)) -> 1295400 | E4: =iferror(D4/B4,0) -> 8.581479 | F4: =sumifs('매출정리 raw'!$J:$J,'매출정리 raw'!$A:$A,$A4) -> 2015300 | G4: =sum(sumifs('매출정리 raw'!$J:$J,'매출정리 raw'!$A:$A,$A4,'매출정리 raw'!$B:$B,"취소완료"),sumifs('매출정리 raw'!$J:$J,'매출정리 raw'!$A:$A,$A4,'매출정리 raw'!$B:$B,"환불완료"),sumifs('매출정리 raw'!$J:$J,'매출정리 raw'!$A:$A,$A4,'매출정리 raw'!$B:$B,"반품완료"),sumifs('매출정리 raw'!$J:$J,'매출정리 raw'!$A:$A,$A4,'매출정리 raw'!$B:$B,"반품요청"),sumifs('매출정리 raw'!$J:$J,'매출정리 raw'!$A:$A,$A4,'매출정리 raw'!$B:$B,"환불요청"),sumifs('매출정리 raw'!$J:$J,'매출정리 raw'!$A:$A,$A4,'매출정리 raw'!$B:$B,"취소요청")) -> 261500 | H4: =F4-G4 -> 1753800 | I4: =iferror(H4/B4,0) -> 11.618186
A5: =A4+1 -> 45963 | B5: =sum(sumifs('파워클릭 raw'!$G:$G,'파워클릭 raw'!$A:$A,$A5),sumifs('Ai매출업 raw'!$D:$D,'Ai매출업 raw'!$A:$A,$A5)) -> 146058 | C5: =sum(sumifs('파워클릭 raw'!$H:$H,'파워클릭 raw'!$A:$A,$A5),sumifs('Ai매출업 raw'!$I:$I,'Ai매출업 raw'!$A:$A,$A5)) -> 29 | D5: =sum(sumifs('파워클릭 raw'!$I:$I,'파워클릭 raw'!$A:$A,$A5),sumifs('Ai매출업 raw'!$J:$J,'Ai매출업 raw'!$A:$A,$A5)) -> 1681200 | E5: =iferror(D5/B5,0) -> 11.510496 | F5: =sumifs('매출정리 raw'!$J:$J,'매출정리 raw'!$A:$A,$A5) -> 2641700 | G5: =sum(sumifs('매출정리 raw'!$J:$J,'매출정리 raw'!$A:$A,$A5,'매출정리 raw'!$B:$B,"취소완료"),sumifs('매출정리 raw'!$J:$J,'매출정리 raw'!$A:$A,$A5,'매출정리 raw'!$B:$B,"환불완료"),sumifs('매출정리 raw'!$J:$J,'매출정리 raw'!$A:$A,$A5,'매출정리 raw'!$B:$B,"반품완료"),sumifs('매출정리 raw'!$J:$J,'매출정리 raw'!$A:$A,$A5,'매출정리 raw'!$B:$B,"반품요청"),sumifs('매출정리 raw'!$J:$J,'매출정리 raw'!$A:$A,$A5,'매출정리 raw'!$B:$B,"환불요청"),sumifs('매출정리 raw'!$J:$J,'매출정리 raw'!$A:$A,$A5,'매출정리 raw'!$B:$B,"취소요청")) -> 525000 | H5: =F5-G5 -> 2116700 | I5: =iferror(H5/B5,0) -> 14.492188
A6: =A5+1 -> 45964 | B6: =sum(sumifs('파워클릭 raw'!$G:$G,'파워클릭 raw'!$A:$A,$A6),sumifs('Ai매출업 raw'!$D:$D,'Ai매출업 raw'!$A:$A,$A6)) -> 133749 | C6: =sum(sumifs('파워클릭 raw'!$H:$H,'파워클릭 raw'!$A:$A,$A6),sumifs('Ai매출업 raw'!$I:$I,'Ai매출업 raw'!$A:$A,$A6)) -> 34 | D6: =sum(sumifs('파워클릭 raw'!$I:$I,'파워클릭 raw'!$A:$A,$A6),sumifs('Ai매출업 raw'!$J:$J,'Ai매출업 raw'!$A:$A,$A6)) -> 2083800 | E6: =iferror(D6/B6,0) -> 15.57993 | F6: =sumifs('매출정리 raw'!$J:$J,'매출정리 raw'!$A:$A,$A6) -> 2878000 | G6: =sum(sumifs('매출정리 raw'!$J:$J,'매출정리 raw'!$A:$A,$A6,'매출정리 raw'!$B:$B,"취소완료"),sumifs('매출정리 raw'!$J:$J,'매출정리 raw'!$A:$A,$A6,'매출정리 raw'!$B:$B,"환불완료"),sumifs('매출정리 raw'!$J:$J,'매출정리 raw'!$A:$A,$A6,'매출정리 raw'!$B:$B,"반품완료"),sumifs('매출정리 raw'!$J:$J,'매출정리 raw'!$A:$A,$A6,'매출정리 raw'!$B:$B,"반품요청"),sumifs('매출정리 raw'!$J:$J,'매출정리 raw'!$A:$A,$A6,'매출정리 raw'!$B:$B,"환불요청"),sumifs('매출정리 raw'!$J:$J,'매출정리 raw'!$A:$A,$A6,'매출정리 raw'!$B:$B,"취소요청")) -> 465400 | H6: =F6-G6 -> 2412600 | I6: =iferror(H6/B6,0) -> 18.038266
A7: =A6+1 -> 45965 | B7: =sum(sumifs('파워클릭 raw'!$G:$G,'파워클릭 raw'!$A:$A,$A7),sumifs('Ai매출업 raw'!$D:$D,'Ai매출업 raw'!$A:$A,$A7)) -> 117689 | C7: =sum(sumifs('파워클릭 raw'!$H:$H,'파워클릭 raw'!$A:$A,$A7),sumifs('Ai매출업 raw'!$I:$I,'Ai매출업 raw'!$A:$A,$A7)) -> 17 | D7: =sum(sumifs('파워클릭 raw'!$I:$I,'파워클릭 raw'!$A:$A,$A7),sumifs('Ai매출업 raw'!$J:$J,'Ai매출업 raw'!$A:$A,$A7)) -> 1018500 | E7: =iferror(D7/B7,0) -> 8.6541648 | F7: =sumifs('매출정리 raw'!$J:$J,'매출정리 raw'!$A:$A,$A7) -> 2281500 | G7: =sum(sumifs('매출정리 raw'!$J:$J,'매출정리 raw'!$A:$A,$A7,'매출정리 raw'!$B:$B,"취소완료"),sumifs('매출정리 raw'!$J:$J,'매출정리 raw'!$A:$A,$A7,'매출정리 raw'!$B:$B,"환불완료"),sumifs('매출정리 raw'!$J:$J,'매출정리 raw'!$A:$A,$A7,'매출정리 raw'!$B:$B,"반품완료"),sumifs('매출정리 raw'!$J:$J,'매출정리 raw'!$A:$A,$A7,'매출정리 raw'!$B:$B,"반품요청"),sumifs('매출정리 raw'!$J:$J,'매출정리 raw'!$A:$A,$A7,'매출정리 raw'!$B:$B,"환불요청"),sumifs('매출정리 raw'!$J:$J,'매출정리 raw'!$A:$A,$A7,'매출정리 raw'!$B:$B,"취소요청")) -> 313000 | H7: =F7-G7 -> 1968500 | I7: =iferror(H7/B7,0) -> 16.726287
A8: =A7+1 -> 45966 | B8: =sum(sumifs('파워클릭 raw'!$G:$G,'파워클릭 raw'!$A:$A,$A8),sumifs('Ai매출업 raw'!$D:$D,'Ai매출업 raw'!$A:$A,$A8)) -> 104544 | C8: =sum(sumifs('파워클릭 raw'!$H:$H,'파워클릭 raw'!$A:$A,$A8),sumifs('Ai매출업 raw'!$I:$I,'Ai매출업 raw'!$A:$A,$A8)) -> 21 | D8: =sum(sumifs('파워클릭 raw'!$I:$I,'파워클릭 raw'!$A:$A,$A8),sumifs('Ai매출업 raw'!$J:$J,'Ai매출업 raw'!$A:$A,$A8)) -> 1222800 | E8: =iferror(D8/B8,0) -> 11.696511 | F8: =sumifs('매출정리 raw'!$J:$J,'매출정리 raw'!$A:$A,$A8) -> 1574800 | G8: =sum(sumifs('매출정리 raw'!$J:$J,'매출정리 raw'!$A:$A,$A8,'매출정리 raw'!$B:$B,"취소완료"),sumifs('매출정리 raw'!$J:$J,'매출정리 raw'!$A:$A,$A8,'매출정리 raw'!$B:$B,"환불완료"),sumifs('매출정리 raw'!$J:$J,'매출정리 raw'!$A:$A,$A8,'매출정리 raw'!$B:$B,"반품완료"),sumifs('매출정리 raw'!$J:$J,'매출정리 raw'!$A:$A,$A8,'매출정리 raw'!$B:$B,"반품요청"),sumifs('매출정리 raw'!$J:$J,'매출정리 raw'!$A:$A,$A8,'매출정리 raw'!$B:$B,"환불요청"),sumifs('매출정리 raw'!$J:$J,'매출정리 raw'!$A:$A,$A8,'매출정리 raw'!$B:$B,"취소요청")) -> 0 | H8: =F8-G8 -> 1574800 | I8: =iferror(H8/B8,0) -> 15.063514
A9: =A8+1 -> 45967 | B9: =sum(sumifs('파워클릭 raw'!$G:$G,'파워클릭 raw'!$A:$A,$A9),sumifs('Ai매출업 raw'!$D:$D,'Ai매출업 raw'!$A:$A,$A9)) -> 126720 | C9: =sum(sumifs('파워클릭 raw'!$H:$H,'파워클릭 raw'!$A:$A,$A9),sumifs('Ai매출업 raw'!$I:$I,'Ai매출업 raw'!$A:$A,$A9)) -> 44 | D9: =sum(sumifs('파워클릭 raw'!$I:$I,'파워클릭 raw'!$A:$A,$A9),sumifs('Ai매출업 raw'!$J:$J,'Ai매출업 raw'!$A:$A,$A9)) -> 2752900 | E9: =iferror(D9/B9,0) -> 21.724274 | F9: =sumifs('매출정리 raw'!$J:$J,'매출정리 raw'!$A:$A,$A9) -> 3453900 | G9: =sum(sumifs('매출정리 raw'!$J:$J,'매출정리 raw'!$A:$A,$A9,'매출정리 raw'!$B:$B,"취소완료"),sumifs('매출정리 raw'!$J:$J,'매출정리 raw'!$A:$A,$A9,'매출정리 raw'!$B:$B,"환불완료"),sumifs('매출정리 raw'!$J:$J,'매출정리 raw'!$A:$A,$A9,'매출정리 raw'!$B:$B,"반품완료"),sumifs('매출정리 raw'!$J:$J,'매출정리 raw'!$A:$A,$A9,'매출정리 raw'!$B:$B,"반품요청"),sumifs('매출정리 raw'!$J:$J,'매출정리 raw'!$A:$A,$A9,'매출정리 raw'!$B:$B,"환불요청"),sumifs('매출정리 raw'!$J:$J,'매출정리 raw'!$A:$A,$A9,'매출정리 raw'!$B:$B,"취소요청")) -> 189000 | H9: =F9-G9 -> 3264900 | I9: =iferror(H9/B9,0) -> 25.764678
A10: =A9+1 -> 45968 | B10: =sum(sumifs('파워클릭 raw'!$G:$G,'파워클릭 raw'!$A:$A,$A10),sumifs('Ai매출업 raw'!$D:$D,'Ai매출업 raw'!$A:$A,$A10)) -> 123750 | C10: =sum(sumifs('파워클릭 raw'!$H:$H,'파워클릭 raw'!$A:$A,$A10),sumifs('Ai매출업 raw'!$I:$I,'Ai매출업 raw'!$A:$A,$A10)) -> 16 | D10: =sum(sumifs('파워클릭 raw'!$I:$I,'파워클릭 raw'!$A:$A,$A10),sumifs('Ai매출업 raw'!$J:$J,'Ai매출업 raw'!$A:$A,$A10)) -> 987200 | E10: =iferror(D10/B10,0) -> 7.9773737 | F10: =sumifs('매출정리 raw'!$J:$J,'매출정리 raw'!$A:$A,$A10) -> 1225300 | G10: =sum(sumifs('매출정리 raw'!$J:$J,'매출정리 raw'!$A:$A,$A10,'매출정리 raw'!$B:$B,"취소완료"),sumifs('매출정리 raw'!$J:$J,'매출정리 raw'!$A:$A,$A10,'매출정리 raw'!$B:$B,"환불완료"),sumifs('매출정리 raw'!$J:$J,'매출정리 raw'!$A:$A,$A10,'매출정리 raw'!$B:$B,"반품완료"),sumifs('매출정리 raw'!$J:$J,'매출정리 raw'!$A:$A,$A10,'매출정리 raw'!$B:$B,"반품요청"),sumifs('매출정리 raw'!$J:$J,'매출정리 raw'!$A:$A,$A10,'매출정리 raw'!$B:$B,"환불요청"),sumifs('매출정리 raw'!$J:$J,'매출정리 raw'!$A:$A,$A10,'매출정리 raw'!$B:$B,"취소요청")) -> 0 | H10: =F10-G10 -> 1225300 | I10: =iferror(H10/B10,0) -> 9.9014141
A11: =A10+1 -> 45969 | B11: =sum(sumifs('파워클릭 raw'!$G:$G,'파워클릭 raw'!$A:$A,$A11),sumifs('Ai매출업 raw'!$D:$D,'Ai매출업 raw'!$A:$A,$A11)) -> 139513 | C11: =sum(sumifs('파워클릭 raw'!$H:$H,'파워클릭 raw'!$A:$A,$A11),sumifs('Ai매출업 raw'!$I:$I,'Ai매출업 raw'!$A:$A,$A11)) -> 29 | D11: =sum(sumifs('파워클릭 raw'!$I:$I,'파워클릭 raw'!$A:$A,$A11),sumifs('Ai매출업 raw'!$J:$J,'Ai매출업 raw'!$A:$A,$A11)) -> 2030600 | E11: =iferror(D11/B11,0) -> 14.554916 | F11: =sumifs('매출정리 raw'!$J:$J,'매출정리 raw'!$A:$A,$A11) -> 1821600 | G11: =sum(sumifs('매출정리 raw'!$J:$J,'매출정리 raw'!$A:$A,$A11,'매출정리 raw'!$B:$B,"취소완료"),sumifs('매출정리 raw'!$J:$J,'매출정리 raw'!$A:$A,$A11,'매출정리 raw'!$B:$B,"환불완료"),sumifs('매출정리 raw'!$J:$J,'매출정리 raw'!$A:$A,$A11,'매출정리 raw'!$B:$B,"반품완료"),sumifs('매출정리 raw'!$J:$J,'매출정리 raw'!$A:$A,$A11,'매출정리 raw'!$B:$B,"반품요청"),sumifs('매출정리 raw'!$J:$J,'매출정리 raw'!$A:$A,$A11,'매출정리 raw'!$B:$B,"환불요청"),sumifs('매출정리 raw'!$J:$J,'매출정리 raw'!$A:$A,$A11,'매출정리 raw'!$B:$B,"취소요청")) -> 24900 | H11: =F11-G11 -> 1796700 | I11: =iferror(H11/B11,0) -> 12.87837
A12: =A11+1 -> 45970 | B12: =sum(sumifs('파워클릭 raw'!$G:$G,'파워클릭 raw'!$A:$A,$A12),sumifs('Ai매출업 raw'!$D:$D,'Ai매출업 raw'!$A:$A,$A12)) -> 170841 | C12: =sum(sumifs('파워클릭 raw'!$H:$H,'파워클릭 raw'!$A:$A,$A12),sumifs('Ai매출업 raw'!$I:$I,'Ai매출업 raw'!$A:$A,$A12)) -> 18 | D12: =sum(sumifs('파워클릭 raw'!$I:$I,'파워클릭 raw'!$A:$A,$A12),sumifs('Ai매출업 raw'!$J:$J,'Ai매출업 raw'!$A:$A,$A12)) -> 1196300 | E12: =iferror(D12/B12,0) -> 7.0024175 | F12: =sumifs('매출정리 raw'!$J:$J,'매출정리 raw'!$A:$A,$A12) -> 2009200 | G12: =sum(sumifs('매출정리 raw'!$J:$J,'매출정리 raw'!$A:$A,$A12,'매출정리 raw'!$B:$B,"취소완료"),sumifs('매출정리 raw'!$J:$J,'매출정리 raw'!$A:$A,$A12,'매출정리 raw'!$B:$B,"환불완료"),sumifs('매출정리 raw'!$J:$J,'매출정리 raw'!$A:$A,$A12,'매출정리 raw'!$B:$B,"반품완료"),sumifs('매출정리 raw'!$J:$J,'매출정리 raw'!$A:$A,$A12,'매출정리 raw'!$B:$B,"반품요청"),sumifs('매출정리 raw'!$J:$J,'매출정리 raw'!$A:$A,$A12,'매출정리 raw'!$B:$B,"환불요청"),sumifs('매출정리 raw'!$J:$J,'매출정리 raw'!$A:$A,$A12,'매출정리 raw'!$B:$B,"취소요청")) -> 237000 | H12: =F12-G12 -> 1772200 | I12: =iferror(H12/B12,0) -> 10.373388
A13: =A12+1 -> 45971 | B13: =sum(sumifs('파워클릭 raw'!$G:$G,'파워클릭 raw'!$A:$A,$A13),sumifs('Ai매출업 raw'!$D:$D,'Ai매출업 raw'!$A:$A,$A13)) -> 163361 | C13: =sum(sumifs('파워클릭 raw'!$H:$H,'파워클릭 raw'!$A:$A,$A13),sumifs('Ai매출업 raw'!$I:$I,'Ai매출업 raw'!$A:$A,$A13)) -> 29 | D13: =sum(sumifs('파워클릭 raw'!$I:$I,'파워클릭 raw'!$A:$A,$A13),sumifs('Ai매출업 raw'!$J:$J,'Ai매출업 raw'!$A:$A,$A13)) -> 1906600 | E13: =iferror(D13/B13,0) -> 11.671084 | F13: =sumifs('매출정리 raw'!$J:$J,'매출정리 raw'!$A:$A,$A13) -> 2791500 | G13: =sum(sumifs('매출정리 raw'!$J:$J,'매출정리 raw'!$A:$A,$A13,'매출정리 raw'!$B:$B,"취소완료"),sumifs('매출정리 raw'!$J:$J,'매출정리 raw'!$A:$A,$A13,'매출정리 raw'!$B:$B,"환불완료"),sumifs('매출정리 raw'!$J:$J,'매출정리 raw'!$A:$A,$A13,'매출정리 raw'!$B:$B,"반품완료"),sumifs('매출정리 raw'!$J:$J,'매출정리 raw'!$A:$A,$A13,'매출정리 raw'!$B:$B,"반품요청"),sumifs('매출정리 raw'!$J:$J,'매출정리 raw'!$A:$A,$A13,'매출정리 raw'!$B:$B,"환불요청"),sumifs('매출정리 raw'!$J:$J,'매출정리 raw'!$A:$A,$A13,'매출정리 raw'!$B:$B,"취소요청")) -> 363000 | H13: =F13-G13 -> 2428500 | I13: =iferror(H13/B13,0) -> 14.865849
A14: =A13+1 -> 45972 | B14: =sum(sumifs('파워클릭 raw'!$G:$G,'파워클릭 raw'!$A:$A,$A14),sumifs('Ai매출업 raw'!$D:$D,'Ai매출업 raw'!$A:$A,$A14)) -> 175417 | C14: =sum(sumifs('파워클릭 raw'!$H:$H,'파워클릭 raw'!$A:$A,$A14),sumifs('Ai매출업 raw'!$I:$I,'Ai매출업 raw'!$A:$A,$A14)) -> 16 | D14: =sum(sumifs('파워클릭 raw'!$I:$I,'파워클릭 raw'!$A:$A,$A14),sumifs('Ai매출업 raw'!$J:$J,'Ai매출업 raw'!$A:$A,$A14)) -> 1100900 | E14: =iferror(D14/B14,0) -> 6.2759026 | F14: =sumifs('매출정리 raw'!$J:$J,'매출정리 raw'!$A:$A,$A14) -> 1966300 | G14: =sum(sumifs('매출정리 raw'!$J:$J,'매출정리 raw'!$A:$A,$A14,'매출정리 raw'!$B:$B,"취소완료"),sumifs('매출정리 raw'!$J:$J,'매출정리 raw'!$A:$A,$A14,'매출정리 raw'!$B:$B,"환불완료"),sumifs('매출정리 raw'!$J:$J,'매출정리 raw'!$A:$A,$A14,'매출정리 raw'!$B:$B,"반품완료"),sumifs('매출정리 raw'!$J:$J,'매출정리 raw'!$A:$A,$A14,'매출정리 raw'!$B:$B,"반품요청"),sumifs('매출정리 raw'!$J:$J,'매출정리 raw'!$A:$A,$A14,'매출정리 raw'!$B:$B,"환불요청"),sumifs('매출정리 raw'!$J:$J,'매출정리 raw'!$A:$A,$A14,'매출정리 raw'!$B:$B,"취소요청")) -> 59000 | H14: =F14-G14 -> 1907300 | I14: =iferror(H14/B14,0) -> 10.872948
A15: =A14+1 -> 45973 | B15: =sum(sumifs('파워클릭 raw'!$G:$G,'파워클릭 raw'!$A:$A,$A15),sumifs('Ai매출업 raw'!$D:$D,'Ai매출업 raw'!$A:$A,$A15)) -> 127204 | C15: =sum(sumifs('파워클릭 raw'!$H:$H,'파워클릭 raw'!$A:$A,$A15),sumifs('Ai매출업 raw'!$I:$I,'Ai매출업 raw'!$A:$A,$A15)) -> 10 | D15: =sum(sumifs('파워클릭 raw'!$I:$I,'파워클릭 raw'!$A:$A,$A15),sumifs('Ai매출업 raw'!$J:$J,'Ai매출업 raw'!$A:$A,$A15)) -> 563900 | E15: =iferror(D15/B15,0) -> 4.4330367 | F15: =sumifs('매출정리 raw'!$J:$J,'매출정리 raw'!$A:$A,$A15) -> 911900 | G15: =sum(sumifs('매출정리 raw'!$J:$J,'매출정리 raw'!$A:$A,$A15,'매출정리 raw'!$B:$B,"취소완료"),sumifs('매출정리 raw'!$J:$J,'매출정리 raw'!$A:$A,$A15,'매출정리 raw'!$B:$B,"환불완료"),sumifs('매출정리 raw'!$J:$J,'매출정리 raw'!$A:$A,$A15,'매출정리 raw'!$B:$B,"반품완료"),sumifs('매출정리 raw'!$J:$J,'매출정리 raw'!$A:$A,$A15,'매출정리 raw'!$B:$B,"반품요청"),sumifs('매출정리 raw'!$J:$J,'매출정리 raw'!$A:$A,$A15,'매출정리 raw'!$B:$B,"환불요청"),sumifs('매출정리 raw'!$J:$J,'매출정리 raw'!$A:$A,$A15,'매출정리 raw'!$B:$B,"취소요청")) -> 0 | H15: =F15-G15 -> 911900 | I15: =iferror(H15/B15,0) -> 7.1687997
A16: =A15+1 -> 45974 | B16: =sum(sumifs('파워클릭 raw'!$G:$G,'파워클릭 raw'!$A:$A,$A16),sumifs('Ai매출업 raw'!$D:$D,'Ai매출업 raw'!$A:$A,$A16)) -> 91608 | C16: =sum(sumifs('파워클릭 raw'!$H:$H,'파워클릭 raw'!$A:$A,$A16),sumifs('Ai매출업 raw'!$I:$I,'Ai매출업 raw'!$A:$A,$A16)) -> 3 | D16: =sum(sumifs('파워클릭 raw'!$I:$I,'파워클릭 raw'!$A:$A,$A16),sumifs('Ai매출업 raw'!$J:$J,'Ai매출업 raw'!$A:$A,$A16)) -> 177000 | E16: =iferror(D16/B16,0) -> 1.9321457 | F16: =sumifs('매출정리 raw'!$J:$J,'매출정리 raw'!$A:$A,$A16) -> 1592500 | G16: =sum(sumifs('매출정리 raw'!$J:$J,'매출정리 raw'!$A:$A,$A16,'매출정리 raw'!$B:$B,"취소완료"),sumifs('매출정리 raw'!$J:$J,'매출정리 raw'!$A:$A,$A16,'매출정리 raw'!$B:$B,"환불완료"),sumifs('매출정리 raw'!$J:$J,'매출정리 raw'!$A:$A,$A16,'매출정리 raw'!$B:$B,"반품완료"),sumifs('매출정리 raw'!$J:$J,'매출정리 raw'!$A:$A,$A16,'매출정리 raw'!$B:$B,"반품요청"),sumifs('매출정리 raw'!$J:$J,'매출정리 raw'!$A:$A,$A16,'매출정리 raw'!$B:$B,"환불요청"),sumifs('매출정리 raw'!$J:$J,'매출정리 raw'!$A:$A,$A16,'매출정리 raw'!$B:$B,"취소요청")) -> 0 | H16: =F16-G16 -> 1592500 | I16: =iferror(H16/B16,0) -> 17.383853
... A34: =A33+1 -> 45992 | B34: =sum(sumifs('파워클릭 raw'!$G:$G,'파워클릭 raw'!$A:$A,$A34),sumifs('Ai매출업 raw'!$D:$D,'Ai매출업 raw'!$A:$A,$A34)) -> 0 | C34: =sum(sumifs('파워클릭 raw'!$H:$H,'파워클릭 raw'!$A:$A,$A34),sumifs('Ai매출업 raw'!$I:$I,'Ai매출업 raw'!$A:$A,$A34)) -> 0 | D34: =sum(sumifs('파워클릭 raw'!$I:$I,'파워클릭 raw'!$A:$A,$A34),sumifs('Ai매출업 raw'!$J:$J,'Ai매출업 raw'!$A:$A,$A34)) -> 0 | E34: =iferror(D34/B34,0) -> 0 | F34: =sumifs('매출정리 raw'!$J:$J,'매출정리 raw'!$A:$A,$A34) -> 0 | G34: =sum(sumifs('매출정리 raw'!$J:$J,'매출정리 raw'!$A:$A,$A34,'매출정리 raw'!$B:$B,"취소완료"),sumifs('매출정리 raw'!$J:$J,'매출정리 raw'!$A:$A,$A34,'매출정리 raw'!$B:$B,"환불완료"),sumifs('매출정리 raw'!$J:$J,'매출정리 raw'!$A:$A,$A34,'매출정리 raw'!$B:$B,"반품완료"),sumifs('매출정리 raw'!$J:$J,'매출정리 raw'!$A:$A,$A34,'매출정리 raw'!$B:$B,"반품요청"),sumifs('매출정리 raw'!$J:$J,'매출정리 raw'!$A:$A,$A34,'매출정리 raw'!$B:$B,"환불요청"),sumifs('매출정리 raw'!$J:$J,'매출정리 raw'!$A:$A,$A34,'매출정리 raw'!$B:$B,"취소요청")) -> 0 | H34: =F34-G34 -> 0 | I34: =iferror(H34/B34,0) -> 0

Sheet 11번가
A1: 머레이 11번가 월별 매출정리
A2: 날짜 | B2: 총광고비용 | C2: 전환수 | D2: 광고센터 전환매출 | E2: 광고센터 ROAS | F2: 장바구니 전환매출 | G2: 장바구니 ROAS | H2: 실매출 판매금액 | I2: 실매출 취소금액 | J2: 실매출 합계 | K2: 실매출 ROAS
A3: 합계 | B3: =sum(B4:B33) -> 1533675 | C3: =sum(C4:C33) -> 175 | D3: =sum(D4:D33) -> 8967700 | E3: =iferror(D3/B3,0) -> 5.8471971 | F3: =sum(F4:F33) -> 14516600 | G3: =iferror(F3/B3,0) -> 9.4652387 | H3: =sum(H4:H33) -> 13086900 | I3: =sum(I4:I33) -> 119900 | J3: =sum(J4:J33) -> 12967000 | K3: =iferror(J3/B3,0) -> 8.4548552
A4: 45962 | B4: =sumifs('11_광고비정리'!$G:$G,'11_광고비정리'!$A:$A,A4) -> 35937 | C4: =sumifS('11_광고비정리'!$H:$H,'11_광고비정리'!$A:$A,A4) -> 5 | D4: =sumifs('11_광고비정리'!$J:$J,'11_광고비정리'!$A:$A,A4) -> 153000 | E4: =iferror(D4/B4,0) -> 4.2574505 | F4: =sumifs('11_광고비정리'!$Y:$Y,'11_광고비정리'!$A:$A,A4) -> 282900 | G4: =iferror(F4/B4,0) -> 7.8721095 | H4: =sumifS('11_매출정리'!$T:$T,'11_매출정리'!$A:$A,A4) -> 242800 | I4: =sum(sumifs('11_매출정리'!$T:$T,'11_매출정리'!$F:$F,"클레임진행중",'11_매출정리'!$A:$A,$A4)) -> 0 | J4: =H4-I4 -> 242800 | K4: =iferror(J4/B4,0) -> 6.7562679
A5: =A4+1 -> 45963 | B5: =sumifs('11_광고비정리'!$G:$G,'11_광고비정리'!$A:$A,A5) -> 48851 | C5: =sumifS('11_광고비정리'!$H:$H,'11_광고비정리'!$A:$A,A5) -> 7 | D5: =sumifs('11_광고비정리'!$J:$J,'11_광고비정리'!$A:$A,A5) -> 437700 | E5: =iferror(D5/B5,0) -> 8.9598985 | F5: =sumifs('11_광고비정리'!$Y:$Y,'11_광고비정리'!$A:$A,A5) -> 177500 | G5: =iferror(F5/B5,0) -> 3.6334978 | H5: =sumifS('11_매출정리'!$T:$T,'11_매출정리'!$A:$A,A5) -> 510600 | I5: =sum(sumifs('11_매출정리'!$T:$T,'11_매출정리'!$F:$F,"클레임진행중",'11_매출정리'!$A:$A,$A5)) -> 0 | J5: =H5-I5 -> 510600 | K5: =iferror(J5/B5,0) -> 10.452191
A6: =A5+1 -> 45964 | B6: =sumifs('11_광고비정리'!$G:$G,'11_광고비정리'!$A:$A,A6) -> 42746 | C6: =sumifS('11_광고비정리'!$H:$H,'11_광고비정리'!$A:$A,A6) -> 10 | D6: =sumifs('11_광고비정리'!$J:$J,'11_광고비정리'!$A:$A,A6) -> 404000 | E6: =iferror(D6/B6,0) -> 9.4511767 | F6: =sumifs('11_광고비정리'!$Y:$Y,'11_광고비정리'!$A:$A,A6) -> 170500 | G6: =iferror(F6/B6,0) -> 3.9886773 | H6: =sumifS('11_매출정리'!$T:$T,'11_매출정리'!$A:$A,A6) -> 469000 | I6: =sum(sumifs('11_매출정리'!$T:$T,'11_매출정리'!$F:$F,"클레임진행중",'11_매출정리'!$A:$A,$A6)) -> 0 | J6: =H6-I6 -> 469000 | K6: =iferror(J6/B6,0) -> 10.971787
A7: =A6+1 -> 45965 | B7: =sumifs('11_광고비정리'!$G:$G,'11_광고비정리'!$A:$A,A7) -> 34408 | C7: =sumifS('11_광고비정리'!$H:$H,'11_광고비정리'!$A:$A,A7) -> 4 | D7: =sumifs('11_광고비정리'!$J:$J,'11_광고비정리'!$A:$A,A7) -> 100400 | E7: =iferror(D7/B7,0) -> 2.9179261 | F7: =sumifs('11_광고비정리'!$Y:$Y,'11_광고비정리'!$A:$A,A7) -> 353300 | G7: =iferror(F7/B7,0) -> 10.267961 | H7: =sumifS('11_매출정리'!$T:$T,'11_매출정리'!$A:$A,A7) -> 1936400 | I7: =sum(sumifs('11_매출정리'!$T:$T,'11_매출정리'!$F:$F,"클레임진행중",'11_매출정리'!$A:$A,$A7)) -> 0 | J7: =H7-I7 -> 1936400 | K7: =iferror(J7/B7,0) -> 56.27761
A8: =A7+1 -> 45966 | B8: =sumifs('11_광고비정리'!$G:$G,'11_광고비정리'!$A:$A,A8) -> 40260 | C8: =sumifS('11_광고비정리'!$H:$H,'11_광고비정리'!$A:$A,A8) -> 6 | D8: =sumifs('11_광고비정리'!$J:$J,'11_광고비정리'!$A:$A,A8) -> 264900 | E8: =iferror(D8/B8,0) -> 6.5797317 | F8: =sumifs('11_광고비정리'!$Y:$Y,'11_광고비정리'!$A:$A,A8) -> 33000 | G8: =iferror(F8/B8,0) -> 0.81967213 | H8: =sumifS('11_매출정리'!$T:$T,'11_매출정리'!$A:$A,A8) -> 225900 | I8: =sum(sumifs('11_매출정리'!$T:$T,'11_매출정리'!$F:$F,"클레임진행중",'11_매출정리'!$A:$A,$A8)) -> 29000 | J8: =H8-I8 -> 196900 | K8: =iferror(J8/B8,0) -> 4.8907104
A9: =A8+1 -> 45967 | B9: =sumifs('11_광고비정리'!$G:$G,'11_광고비정리'!$A:$A,A9) -> 42031 | C9: =sumifS('11_광고비정리'!$H:$H,'11_광고비정리'!$A:$A,A9) -> 4 | D9: =sumifs('11_광고비정리'!$J:$J,'11_광고비정리'!$A:$A,A9) -> 127400 | E9: =iferror(D9/B9,0) -> 3.0310961 | F9: =sumifs('11_광고비정리'!$Y:$Y,'11_광고비정리'!$A:$A,A9) -> 276800 | G9: =iferror(F9/B9,0) -> 6.5856154 | H9: =sumifS('11_매출정리'!$T:$T,'11_매출정리'!$A:$A,A9) -> 292400 | I9: =sum(sumifs('11_매출정리'!$T:$T,'11_매출정리'!$F:$F,"클레임진행중",'11_매출정리'!$A:$A,$A9)) -> 0 | J9: =H9-I9 -> 292400 | K9: =iferror(J9/B9,0) -> 6.95677
A10: =A9+1 -> 45968 | B10: =sumifs('11_광고비정리'!$G:$G,'11_광고비정리'!$A:$A,A10) -> 41349 | C10: =sumifS('11_광고비정리'!$H:$H,'11_광고비정리'!$A:$A,A10) -> 2 | D10: =sumifs('11_광고비정리'!$J:$J,'11_광고비정리'!$A:$A,A10) -> 133000 | E10: =iferror(D10/B10,0) -> 3.2165228 | F10: =sumifs('11_광고비정리'!$Y:$Y,'11_광고비정리'!$A:$A,A10) -> 412600 | G10: =iferror(F10/B10,0) -> 9.9784759 | H10: =sumifS('11_매출정리'!$T:$T,'11_매출정리'!$A:$A,A10) -> 74000 | I10: =sum(sumifs('11_매출정리'!$T:$T,'11_매출정리'!$F:$F,"클레임진행중",'11_매출정리'!$A:$A,$A10)) -> 0 | J10: =H10-I10 -> 74000 | K10: =iferror(J10/B10,0) -> 1.7896442
A11: =A10+1 -> 45969 | B11: =sumifs('11_광고비정리'!$G:$G,'11_광고비정리'!$A:$A,A11) -> 46695 | C11: =sumifS('11_광고비정리'!$H:$H,'11_광고비정리'!$A:$A,A11) -> 4 | D11: =sumifs('11_광고비정리'!$J:$J,'11_광고비정리'!$A:$A,A11) -> 224900 | E11: =iferror(D11/B11,0) -> 4.8163615 | F11: =sumifs('11_광고비정리'!$Y:$Y,'11_광고비정리'!$A:$A,A11) -> 220800 | G11: =iferror(F11/B11,0) -> 4.7285577 | H11: =sumifS('11_매출정리'!$T:$T,'11_매출정리'!$A:$A,A11) -> 283900 | I11: =sum(sumifs('11_매출정리'!$T:$T,'11_매출정리'!$F:$F,"클레임진행중",'11_매출정리'!$A:$A,$A11)) -> 0 | J11: =H11-I11 -> 283900 | K11: =iferror(J11/B11,0) -> 6.0798801
A12: =A11+1 -> 45970 | B12: =sumifs('11_광고비정리'!$G:$G,'11_광고비정리'!$A:$A,A12) -> 43835 | C12: =sumifS('11_광고비정리'!$H:$H,'11_광고비정리'!$A:$A,A12) -> 2 | D12: =sumifs('11_광고비정리'!$J:$J,'11_광고비정리'!$A:$A,A12) -> 30000 | E12: =iferror(D12/B12,0) -> 0.68438462 | F12: =sumifs('11_광고비정리'!$Y:$Y,'11_광고비정리'!$A:$A,A12) -> 672500 | G12: =iferror(F12/B12,0) -> 15.341622 | H12: =sumifS('11_매출정리'!$T:$T,'11_매출정리'!$A:$A,A12) -> 45000 | I12: =sum(sumifs('11_매출정리'!$T:$T,'11_매출정리'!$F:$F,"클레임진행중",'11_매출정리'!$A:$A,$A12)) -> 0 | J12: =H12-I12 -> 45000 | K12: =iferror(J12/B12,0) -> 1.0265769
A13: =A12+1 -> 45971 | B13: =sumifs('11_광고비정리'!$G:$G,'11_광고비정리'!$A:$A,A13) -> 40964 | C13: =sumifS('11_광고비정리'!$H:$H,'11_광고비정리'!$A:$A,A13) -> 6 | D13: =sumifs('11_광고비정리'!$J:$J,'11_광고비정리'!$A:$A,A13) -> 250100 | E13: =iferror(D13/B13,0) -> 6.1053608 | F13: =sumifs('11_광고비정리'!$Y:$Y,'11_광고비정리'!$A:$A,A13) -> 458600 | G13: =iferror(F13/B13,0) -> 11.195196 | H13: =sumifS('11_매출정리'!$T:$T,'11_매출정리'!$A:$A,A13) -> 561200 | I13: =sum(sumifs('11_매출정리'!$T:$T,'11_매출정리'!$F:$F,"클레임진행중",'11_매출정리'!$A:$A,$A13)) -> 0 | J13: =H13-I13 -> 561200 | K13: =iferror(J13/B13,0) -> 13.699834
A14: =A13+1 -> 45972 | B14: =sumifs('11_광고비정리'!$G:$G,'11_광고비정리'!$A:$A,A14) -> 69949 | C14: =sumifS('11_광고비정리'!$H:$H,'11_광고비정리'!$A:$A,A14) -> 11 | D14: =sumifs('11_광고비정리'!$J:$J,'11_광고비정리'!$A:$A,A14) -> 515300 | E14: =iferror(D14/B14,0) -> 7.3667958 | F14: =sumifs('11_광고비정리'!$Y:$Y,'11_광고비정리'!$A:$A,A14) -> 478400 | G14: =iferror(F14/B14,0) -> 6.8392686 | H14: =sumifS('11_매출정리'!$T:$T,'11_매출정리'!$A:$A,A14) -> 669800 | I14: =sum(sumifs('11_매출정리'!$T:$T,'11_매출정리'!$F:$F,"클레임진행중",'11_매출정리'!$A:$A,$A14)) -> 0 | J14: =H14-I14 -> 669800 | K14: =iferror(J14/B14,0) -> 9.5755479
A15: =A14+1 -> 45973 | B15: =sumifs('11_광고비정리'!$G:$G,'11_광고비정리'!$A:$A,A15) -> 23078 | C15: =sumifS('11_광고비정리'!$H:$H,'11_광고비정리'!$A:$A,A15) -> 2 | D15: =sumifs('11_광고비정리'!$J:$J,'11_광고비정리'!$A:$A,A15) -> 45000 | E15: =iferror(D15/B15,0) -> 1.949909 | F15: =sumifs('11_광고비정리'!$Y:$Y,'11_광고비정리'!$A:$A,A15) -> 220900 | G15: =iferror(F15/B15,0) -> 9.5718866 | H15: =sumifS('11_매출정리'!$T:$T,'11_매출정리'!$A:$A,A15) -> 125800 | I15: =sum(sumifs('11_매출정리'!$T:$T,'11_매출정리'!$F:$F,"클레임진행중",'11_매출정리'!$A:$A,$A15)) -> 0 | J15: =H15-I15 -> 125800 | K15: =iferror(J15/B15,0) -> 5.451079
A16: =A15+1 -> 45974 | B16: =sumifs('11_광고비정리'!$G:$G,'11_광고비정리'!$A:$A,A16) -> 32395 | C16: =sumifS('11_광고비정리'!$H:$H,'11_광고비정리'!$A:$A,A16) -> 4 | D16: =sumifs('11_광고비정리'!$J:$J,'11_광고비정리'!$A:$A,A16) -> 159600 | E16: =iferror(D16/B16,0) -> 4.9266862 | F16: =sumifs('11_광고비정리'!$Y:$Y,'11_광고비정리'!$A:$A,A16) -> 368800 | G16: =iferror(F16/B16,0) -> 11.384473 | H16: =sumifS('11_매출정리'!$T:$T,'11_매출정리'!$A:$A,A16) -> 79800 | I16: =sum(sumifs('11_매출정리'!$T:$T,'11_매출정리'!$F:$F,"클레임진행중",'11_매출정리'!$A:$A,$A16)) -> 0 | J16: =H16-I16 -> 79800 | K16: =iferror(J16/B16,0) -> 2.4633431
... A34: =A33+1 -> 45992 | B34: =sumifs('11_광고비정리'!$G:$G,'11_광고비정리'!$A:$A,A34) -> 0 | C34: =sumifS('11_광고비정리'!$H:$H,'11_광고비정리'!$A:$A,A34) -> 0 | D34: =sumifs('11_광고비정리'!$J:$J,'11_광고비정리'!$A:$A,A34) -> 0 | E34: =iferror(D34/B34,0) -> 0 | F34: =sumifs('11_광고비정리'!$Y:$Y,'11_광고비정리'!$A:$A,A34) -> 0 | G34: =iferror(F34/B34,0) -> 0 | H34: =sumifS('11_매출정리'!$T:$T,'11_매출정리'!$A:$A,A34) -> 0 | I34: =sum(sumifs('11_매출정리'!$T:$T,'11_매출정리'!$F:$F,"클레임진행중",'11_매출정리'!$A:$A,$A34)) -> 0 | J34: =H34-I34 -> 0 | K34: =iferror(J34/B34,0) -> 0

Sheet 매출정리 raw
A1: 날짜 | B1: 진행상태 | C1: 판매아이디 | D1: 구매자아이디 | E1: 주문번호 | F1: 상품번호 | G1: 상품명 | H1: 구매자명 | I1: 수령인명 | J1: 구매금액 | K1: 수량 | L1: 결제일 | M1: 배송완료일자 | N1: 송금완료일자 | O1: SSG 상품번호 | P1: SSG 원주문번호
A2: =iferror(date(year(L2),month(L2),day(L2)),"날짜") -> 45991 | B2: 배송중 | C2: 지마켓(murraymall) | D2: user887130 | E2: 4374490737 | F2: 2106845960 | G2: 머레이 마사지건 M-GUN 4종 최대 출력 3200rpm 실버 | H2: 오해든 | I2: 오해든 | J2: 34900 | K2: 1 | L2: 45991.99
A3: =iferror(date(year(L3),month(L3),day(L3)),"날짜") -> 45991 | B3: 배송중 | C3: 지마켓(murraymall) | D3: user805705 | E3: 4374464459 | F3: 4180306338 | G3: 한일의료기 정품 그래핀 5세대 탄소매트 전기매트 온열매트 (더블 135x180cm) 정품 공급처 | H3: name-1341174285 | I3: name-1341174285 | J3: 65000 | K3: 1 | L3: 45991.952
A4: =iferror(date(year(L4),month(L4),day(L4)),"날짜") -> 45991 | B4: 배송중 | C4: 지마켓(murraymall) | D4: user520802 | E4: 4374459371 | F4: 4188494215 | G4: 1+1 컬러2in1 도킹형 일체형 휴대폰 보조배터리 (C타입/8핀) 산뜻한 디자인 든든한 1+1 가성비 | H4: name-1611071225 | I4: name-1611071225 | J4: 24900 | K4: 1 | L4: 45991.945
A5: =iferror(date(year(L5),month(L5),day(L5)),"날짜") -> 45991 | B5: 배송중 | C5: 옥션(murraymall) | D5: user402372 | E5: 2541561826 | F5: E761279609 | G5: 한일의료기 정품 그래핀 5세대 탄소매트 전기매트 온열매트 (싱글 100x180cm) 정품 공급처 | H5: name-2777842988 | I5: name-2777842988 | J5: 59000 | K5: 1 | L5: 45991.937
A6: =iferror(date(year(L6),month(L6),day(L6)),"날짜") -> 45991 | B6: 배송중 | C6: 지마켓(murraymall) | D6: user726389 | E6: 4374453826 | F6: 4180306338 | G6: 한일의료기 정품 그래핀 5세대 탄소매트 전기매트 온열매트 (더블 135x180cm) 정품 공급처 | H6: name-328962377 | I6: name-328962377 | J6: 65000 | K6: 1 | L6: 45991.936
A7: =iferror(date(year(L7),month(L7),day(L7)),"날짜") -> 45991 | B7: 취소완료 | C7: 지마켓(murraymall) | D7: user868789 | E7: 4374423308 | F7: 4180303895 | G7: 한일의료기 정품 그래핀 5세대 탄소매트 전기매트 온열매트 (싱글 100x180cm) 정품 공급처 | H7: 조바다 | I7: 조바다 | J7: 59000 | K7: 1 | L7: 45991.888
A8: =iferror(date(year(L8),month(L8),day(L8)),"날짜") -> 45991 | B8: 환불완료 | C8: 옥션(murraymall) | D8: user753265 | E8: 2541548433 | F8: E761279609 | G8: 한일의료기 정품 그래핀 5세대 탄소매트 전기매트 온열매트 (싱글 100x180cm) 정품 공급처 | H8: name-3858108940 | I8: name-2407036560 | J8: 59000 | K8: 1 | L8: 45991.876
A9: =iferror(date(year(L9),month(L9),day(L9)),"날짜") -> 45991 | B9: 배송중 | C9: 지마켓(murraymall) | D9: user283650 | E9: 4374383906 | F9: 1784307306 | G9: 머레이 디지털 펜 보이스레코더/학습강의 PV-3000 16GB 최대 180시간녹음 선명한 음질 볼펜녹음기 | H9: name-3124920350 | I9: name-3124920350 | J9: 47900 | K9: 1 | L9: 45991.818
A10: =iferror(date(year(L10),month(L10),day(L10)),"날짜") -> 45991 | B10: 배송중 | C10: 지마켓(murraymall) | D10: user142805 | E10: 4374336116 | F10: 4113880902 | G10: 초강력 간편 휴대용/차량용 코털제거기 코털정리기 (블랙) | H10: 이라온 | I10: 이라온 | J10: 14500 | K10: 1 | L10: 45991.696
A11: =iferror(date(year(L11),month(L11),day(L11)),"날짜") -> 45991 | B11: 배송중 | C11: 지마켓(murraymall) | D11: user699367 | E11: 4374325405 | F11: 2822272510 | G11: 유무선 충전가능한 레이펜슬3세대 애플펜슬 2세대 호환 짭플펜슬 최고의 가성비 | H11: 윤한별 | I11: 윤한별 | J11: 31500 | K11: 1 | L11: 45991.666
A12: =iferror(date(year(L12),month(L12),day(L12)),"날짜") -> 45990 | B12: 배송중 | C12: 지마켓(murraymall) | D12: user474832 | E12: 4374170515 | F12: 3252522586 | G12: 세척편한 인테리어 물멍가습기 미니 초음파 가습기 HUMI-10 최대 10시간 연속사용 | H12: name-2266361694 | I12: name-2266361694 | J12: 43900 | K12: 1 | L12: 45990.952
A13: =iferror(date(year(L13),month(L13),day(L13)),"날짜") -> 45990 | B13: 취소완료 | C13: 지마켓(murraymall) | D13: user360070 | E13: 4374150309 | F13: 4544686745 | G13: 한일의료기 탄소 매트 극세사 더블 HIM-3000D 라이트그레이 정품 공급처 | H13: 라온무역 | I13: 나래유통 | J13: 119000 | K13: 1 | L13: 45990.897
A14: =iferror(date(year(L14),month(L14),day(L14)),"날짜") -> 45990 | B14: 배송중 | C14: 지마켓(murraymall) | D14: user695697 | E14: 4374121722 | F14: 4180306338 | G14: 한일의료기 정품 그래핀 5세대 탄소매트 전기매트 온열매트 (더블 135x180cm) 정품 공급처 | H14: 임온새 | I14: 임온새 | J14: 65000 | K14: 1 | L14: 45990.815
A15: =iferror(date(year(L15),month(L15),day(L15)),"날짜") -> 45990 | B15: 배송중 | C15: 옥션(murraymall) | D15: user991013 | E15: 2541439808 | F15: E761279609 | G15: 한일의료기 정품 그래핀 5세대 탄소매트 전기매트 온열매트 (싱글 100x180cm) 정품 공급처 | H15: name-3362315446 | I15: 서푸른 | J15: 59000 | K15: 1 | L15: 45990.801
A16: =iferror(date(year(L16),month(L16),day(L16)),"날짜") -> 45990 | B16: 배송중 | C16: 옥션(murraymall) | D16: user603439 | E16: 2541433041 | F16: E761279609 | G16: 한일의료기 정품 그래핀 5세대 탄소매트 전기매트 온열매트 (싱글 100x180cm) 정품 공급처 | H16: name-3722060051 | I16: name-1331521670 | J16: 59000 | K16: 1 | L16: 45990.732
A17: =iferror(date(year(L17),month(L17),day(L17)),"날짜") -> 45990 | B17: 배송중 | C17: 옥션(murraymall) | D17: user567850 | E17: 2541415252 | F17: E761279609 | G17: 한일의료기 정품 그래핀 5세대 탄소매트 전기매트 온열매트 (싱글 100x180cm) 정품 공급처 | H17: name-3007858657 | I17: name-3007858657 | J17: 59000 | K17: 1 | L17: 45990.555
A18: =iferror(date(year(L18),month(L18),day(L18)),"날짜") -> 45990 | B18: 배송중 | C18: 지마켓(murraymall) | D18: user578147 | E18: 4374027264 | F18: 2702301401 | G18: 3in1 무선충전기 갤럭시워치 애플워치 갤럭시버즈 에어팟 무선충전 가능 데스크테리어의 완성 | H18: name-3463409686 | I18: name-3463409686 | J18: 29900 | K18: 1 | L18: 45990.484
A19: =iferror(date(year(L19),month(L19),day(L19)),"날짜") -> 45990 | B19: 배송중 | C19: 지마켓(murraymall) | D19: user441810 | E19: 4373999598 | F19: 4113888539 | G19: 초강력 간편 휴대용/차량용 코털제거기 코털정리기 (오렌지) | H19: name-3237383314 | I19: name-3237383314 | J19: 14500 | K19: 1 | L19: 45990.401
A20: =iferror(date(year(L20),month(L20),day(L20)),"날짜") -> 45990 | B20: 배송중 | C20: 지마켓(murraymall) | D20: user352682 | E20: 4373973186 | F20: 4180306338 | G20: 한일의료기 정품 그래핀 5세대 탄소매트 전기매트 온열매트 (더블 135x180cm) 정품 공급처 | H20: name-1781817282 | I20: name-1781817282 | J20: 65000 | K20: 1 | L20: 45990.235
A21: =iferror(date(year(L21),month(L21),day(L21)),"날짜") -> 45990 | B21: 배송중 | C21: 지마켓(murraymall) | D21: user267582 | E21: 4373972243 | F21: 4180303895 | G21: 한일의료기 정품 그래핀 5세대 탄소매트 전기매트 온열매트 (싱글 100x180cm) 정품 공급처 | H21: name-1363229111 | I21: name-1363229111 | J21: 59000 | K21: 1 | L21: 45990.218
A22: =iferror(date(year(L22),month(L22),day(L22)),"날짜") -> 45989 | B22: 배송중 | C22: 지마켓(murraymall) | D22: user543819 | E22: 4373857020 | F22: 4180303895 | G22: 한일의료기 정품 그래핀 5세대 탄소매트 전기매트 온열매트 (싱글 100x180cm) 정품 공급처 | H22: 김아름 | I22: 김아름 | J22: 59000 | K22: 1 | L22: 45989.709
A23: =iferror(date(year(L23),month(L23),day(L23)),"날짜") -> 45989 | B23: 배송중 | C23: 옥션(murraymall) | D23: user855187 | E23: 2541346790 | F23: E761279609 | G23: 한일의료기 정품 그래핀 5세대 탄소매트 전기매트 온열매트 (싱글 100x180cm) 정품 공급처 | H23: name-3612244018 | I23: name-3612244018 | J23: 59000 | K23: 1 | L23: 45989.694
A24: =iferror(date(year(L24),month(L24),day(L24)),"날짜") -> 45989 | B24: 배송중 | C24: 옥션(murraymall) | D24: user842227 | E24: 2541341989 | F24: D907274905 | G24: 머레이 폴더블 스탠딩 3in1 무선충전기 Z10 갤럭시워치 애플워치 갤럭시S25 충전기 단언컨데 가장 실용적 | H24: name-4105668465 | I24: name-4105668465 | J24: 19900 | K24: 1 | L24: 45989.654
A25: =iferror(date(year(L25),month(L25),day(L25)),"날짜") -> 45989 | B25: 배송중 | C25: 지마켓(murraymall) | D25: user656241 | E25: 4373800449 | F25: 4180303895 | G25: 한일의료기 정품 그래핀 5세대 탄소매트 전기매트 온열매트 (싱글 100x180cm) 정품 공급처 | H25: name-221359303 | I25: name-221359303 | J25: 59000 | K25: 1 | L25: 45989.59
A26: =iferror(date(year(L26),month(L26),day(L26)),"날짜") -> 45989 | B26: 배송완료 | C26: 지마켓(murraymall) | D26: user916779 | E26: 4373748292 | F26: 4180306338 | G26: 한일의료기 정품 그래핀 5세대 탄소매트 전기매트 온열매트 (더블 135x180cm) 정품 공급처 | H26: name-1412690750 | I26: name-1412690750 | J26: 65000 | K26: 1 | L26: 45989.488 | M26: 45990.549
A27: =iferror(date(year(L27),month(L27),day(L27)),"날짜") -> 45989 | B27: 구매결정완료 | C27: 지마켓(murraymall) | D27: user580880 | E27: 4373734440 | F27: 2702301401 | G27: 3in1 무선충전기 갤럭시워치 애플워치 갤럭시버즈 에어팟 무선충전 가능 데스크테리어의 완성 | H27: name-1993244661 | I27: name-3657272740 | J27: 29900 | K27: 1 | L27: 45989.466 | M27: 45990.6
A28: =iferror(date(year(L28),month(L28),day(L28)),"날짜") -> 45989 | B28: 배송완료 | C28: 지마켓(murraymall) | D28: user385511 | E28: 4373721824 | F28: 4180303895 | G28: 한일의료기 정품 그래핀 5세대 탄소매트 전기매트 온열매트 (싱글 100x180cm) 정품 공급처 | H28: name-1635677639 | I28: name-1635677639 | J28: 59000 | K28: 1 | L28: 45989.448 | M28: 45990.591
A29: =iferror(date(year(L29),month(L29),day(L29)),"날짜") -> 45989 | B29: 배송완료 | C29: 지마켓(murraymall) | D29: user816384 | E29: 4373706964 | F29: 4180303895 | G29: 한일의료기 정품 그래핀 5세대 탄소매트 전기매트 온열매트 (싱글 100x180cm) 정품 공급처 | H29: 임해든 | I29: 임해든 | J29: 59000 | K29: 1 | L29: 45989.426 | M29: 45990.48
A30: =iferror(date(year(L30),month(L30),day(L30)),"날짜") -> 45988 | B30: 배송완료 | C30: 지마켓(murraymall) | D30: user144686 | E30: 4373609042 | F30: 2793594584 | G30: 정교하고 튼튼한 메탈펜촉 4개입 세트 애플펜슬 1 2세대 호환 교체가능 | H30: 이초록 | I30: 이초록 | J30: 14900 | K30: 1 | L30: 45988.957 | M30: 45990.702
A31: =iferror(date(year(L31),month(L31),day(L31)),"날짜") -> 45988 | B31: 배송완료 | C31: 지마켓(murraymall) | D31: user139348 | E31: 4373588166 | F31: 4180303895 | G31: 한일의료기 정품 그래핀 5세대 탄소매트 전기매트 온열매트 (싱글 100x180cm) 정품 공급처 | H31: name-1958500366 | I31: name-939389352 | J31: 59000 | K31: 1 | L31: 45988.907 | M31: 45990.438
A32: =iferror(date(year(L32),month(L32),day(L32)),"날짜") -> 45988 | B32: 배송완료 | C32: 지마켓(murraymall) | D32: user376345 | E32: 4373545258 | F32: 4188494215 | G32: 1+1 컬러2in1 도킹형 일체형 휴대폰 보조배터리 (C타입/8핀) 산뜻한 디자인 든든한 1+1 가성비 | H32: name-672817314 | I32: name-672817314 | J32: 24900 | K32: 1 | L32: 45988.79 | M32: 45990.487
A33: =iferror(date(year(L33),month(L33),day(L33)),"날짜") -> 45988 | B33: 배송완료 | C33: 지마켓(murraymall) | D33: user376345 | E33: 4373545257 | F33: 4188494215 | G33: 1+1 컬러2in1 도킹형 일체형 휴대폰 보조배터리 (C타입/8핀) 산뜻한 디자인 든든한 1+1 가성비 | H33: name-672817314 | I33: name-672817314 | J33: 24900 | K33: 1 | L33: 45988.79 | M33: 45990.487
A34: =iferror(date(year(L34),month(L34),day(L34)),"날짜") -> 45988 | B34: 배송완료 | C34: 지마켓(murraymall) | D34: user376345 | E34: 4373545259 | F34: 4188494215 | G34: 1+1 컬러2in1 도킹형 일체형 휴대폰 보조배터리 (C타입/8핀) 산뜻한 디자인 든든한 1+1 가성비 | H34: name-672817314 | I34: name-672817314 | J34: 24900 | K34: 1 | L34: 45988.79 | M34: 45990.487
A35: =iferror(date(year(L35),month(L35),day(L35)),"날짜") -> 45988 | B35: 배송완료 | C35: 지마켓(murraymall) | D35: user914470 | E35: 4373462536 | F35: 4180303895 | G35: 한일의료기 정품 그래핀 5세대 탄소매트 전기매트 온열매트 (싱글 100x180cm) 정품 공급처 | H35: name-2276889280 | I35: name-2276889280 | J35: 59000 | K35: 1 | L35: 45988.602 | M35: 45990.577
A36: =iferror(date(year(L36),month(L36),day(L36)),"날짜") -> 45988 | B36: 배송완료 | C36: 지마켓(murraymall) | D36: user349432 | E36: 4373425056 | F36: 4180303895 | G36: 한일의료기 정품 그래핀 5세대 탄소매트 전기매트 온열매트 (싱글 100x180cm) 정품 공급처 | H36: name-1554764709 | I36: name-1554764709 | J36: 59000 | K36: 1 | L36: 45988.541 | M36: 45989.702
A37: =iferror(date(year(L37),month(L37),day(L37)),"날짜") -> 45988 | B37: 배송완료 | C37: 옥션(murraymall) | D37: user415789 | E37: 2541213123 | F37: E761279609 | G37: 한일의료기 정품 그래핀 5세대 탄소매트 전기매트 온열매트 (싱글 100x180cm) 정품 공급처 | H37: name-3359976734 | I37: name-3673421376 | J37: 59000 | K37: 1 | L37: 45988.508 | M37: 45989.585
A38: =iferror(date(year(L38),month(L38),day(L38)),"날짜") -> 45988 | B38: 배송완료 | C38: 지마켓(murraymall) | D38: user281150 | E38: 4373325780 | F38: 1784307306 | G38: 머레이 디지털 펜 보이스레코더/학습강의 PV-3000 16GB 최대 180시간녹음 선명한 음질 볼펜녹음기 | H38: name-3335149529 | I38: 윤지음 | J38: 47900 | K38: 1 | L38: 45988.385 | M38: 45989.494
A39: =iferror(date(year(L39),month(L39),day(L39)),"날짜") -> 45988 | B39: 배송완료 | C39: 옥션(murraymall) | D39: user551355 | E39: 2541177120 | F39: C942431166 | G39: 레인보우LED 블루투스마이크 노래방마이크 블루투스스피커 블랙 유치원/학교 대량구매 인기상품 | H39: name-676073073 | I39: name-3069448111 | J39: 144000 | K39: 2 | L39: 45988.145 | M39: 45989.534
A40: =iferror(date(year(L40),month(L40),day(L40)),"날짜") -> 45988 | B40: 환불완료 | C40: 옥션(murraymall) | D40: user551355 | E40: 2541175572 | F40: C942431166 | G40: 레인보우LED 블루투스마이크 노래방마이크 블루투스스피커 블랙 유치원/학교 대량구매 인기상품 | H40: name-676073073 | I40: name-676073073 | J40: 144000 | K40: 2 | L40: 45988.09
...

Sheet 파워클릭 raw
A2: 날짜 | B2: 노출수 | C2: 클릭수 | D2: 클릭률 | E2: 평균노출순위 | F2: 평균클릭비용 | G2: 총비용 | H2: 구매수 | I2: 구매금액 | J2: 전환율 | K2: 광고수익률
A3: 45962 | B3: 23875 | C3: 191 | D3: 0.8 | E3: 10 | F3: 647 | G3: 123486 | H3: 16 | I3: 798400 | J3: 8.38 | K3: 646.55
A4: 45963 | B4: 25345 | C4: 182 | D4: 0.72 | E4: 10 | F4: 654 | G4: 118965 | H4: 21 | I4: 1153200 | J4: 11.54 | K4: 969.36
A5: 45964 | B5: 21864 | C5: 159 | D5: 0.73 | E5: 12 | F5: 672 | G5: 106810 | H5: 24 | I5: 1357900 | J5: 15.09 | K5: 1271.32
A6: 45965 | B6: 19912 | C6: 137 | D6: 0.69 | E6: 12 | F6: 668 | G6: 91509 | H6: 11 | I6: 604500 | J6: 8.03 | K6: 660.59
A7: 45966 | B7: 21588 | C7: 125 | D7: 0.58 | E7: 12 | F7: 620 | G7: 77473 | H7: 11 | I7: 580800 | J7: 8.8 | K7: 749.68
A8: 45967 | B8: 18757 | C8: 105 | D8: 0.56 | E8: 12 | F8: 684 | G8: 71786 | H8: 14 | I8: 856900 | J8: 13.33 | K8: 1193.69
A9: 45968 | B9: 17753 | C9: 103 | D9: 0.58 | E9: 11 | F9: 714 | G9: 73568 | H9: 7 | I9: 374700 | J9: 6.8 | K9: 509.32
A10: 45969 | B10: 26900 | C10: 110 | D10: 0.41 | E10: 9 | F10: 680 | G10: 74833 | H10: 11 | I10: 769900 | J10: 10 | K10: 1028.82
A11: 45970 | B11: 30316 | C11: 161 | D11: 0.53 | E11: 9 | F11: 638 | G11: 102740 | H11: 8 | I11: 477500 | J11: 4.97 | K11: 464.77
A12: 45971 | B12: 23643 | C12: 137 | D12: 0.58 | E12: 12 | F12: 617 | G12: 84469 | H12: 13 | I12: 824800 | J12: 9.49 | K12: 976.45
A13: 45972 | B13: 27095 | C13: 148 | D13: 0.55 | E13: 12 | F13: 642 | G13: 95051 | H13: 7 | I13: 463000 | J13: 4.73 | K13: 487.11
A14: 45973 | B14: 20154 | C14: 71 | D14: 0.35 | E14: 12 | F14: 688 | G14: 48818 | H14: 7 | I14: 426000 | J14: 9.86 | K14: 872.63
... A32: 45991 | B32: 56621 | C32: 93 | D32: 0.16 | E32: 11 | F32: 651 | G32: 60577 | H32: 4 | I32: 184400 | J32: 4.3 | K32: 304.41

Sheet Ai매출업 raw
A1: 날짜별 | B1: 클릭수 | C1: 평균클릭비용 | D1: 총비용 | E1: 광고상품기준-주문수 | F1: 광고상품기준-구매수 | G1: 광고상품기준-구매금액 | H1: 판매자기준-주문수 | I1: 판매자기준-구매수 | J1: 판매자기준-구매금액 | K1: 판매자기준-전환율 | L1: 판매자기준-광고수익률
A2: 45962 | B2: 68 | C2: 404 | D2: 27467 | E2: 5 | F2: 7 | G2: 378000 | H2: 6 | I2: 8 | J2: 497000 | K2: 0.1176 | L2: 18.0944
A3: 45963 | B3: 65 | C3: 417 | D3: 27093 | E3: 6 | F3: 8 | G3: 528000 | H3: 6 | I3: 8 | J3: 528000 | K3: 0.1231 | L3: 19.4884
A4: 45964 | B4: 68 | C4: 396 | D4: 26939 | E4: 8 | F4: 10 | G4: 725900 | H4: 8 | I4: 10 | J4: 725900 | K4: 0.1471 | L4: 26.9461
A5: 45965 | B5: 66 | C5: 397 | D5: 26180 | E5: 5 | F5: 6 | G5: 414000 | H5: 5 | I5: 6 | J5: 414000 | K5: 0.0909 | L5: 15.8136
A6: 45966 | B6: 67 | C6: 404 | D6: 27071 | E6: 6 | F6: 10 | G6: 642000 | H6: 6 | I6: 10 | J6: 642000 | K6: 0.1493 | L6: 23.7154
A7: 45967 | B7: 134 | C7: 410 | D7: 54934 | E7: 5 | F7: 28 | G7: 1712000 | H7: 7 | I7: 30 | J7: 1896000 | K7: 0.2239 | L7: 34.5141
A8: 45968 | B8: 122 | C8: 411 | D8: 50182 | E8: 8 | F8: 9 | G8: 612500 | H8: 8 | I8: 9 | J8: 612500 | K8: 0.0738 | L8: 12.2056
A9: 45969 | B9: 164 | C9: 394 | D9: 64680 | E9: 10 | F9: 13 | G9: 749700 | H9: 13 | I9: 18 | J9: 1260700 | K9: 0.1098 | L9: 19.4913
A10: 45970 | B10: 173 | C10: 394 | D10: 68101 | E10: 8 | F10: 9 | G10: 653800 | H10: 9 | I10: 10 | J10: 718800 | K10: 0.0578 | L10: 10.5549
A11: 45971 | B11: 201 | C11: 392 | D11: 78892 | E11: 12 | F11: 15 | G11: 1016800 | H11: 13 | I11: 16 | J11: 1081800 | K11: 0.0796 | L11: 13.7124
A12: 45972 | B12: 202 | C12: 398 | D12: 80366 | E12: 7 | F12: 9 | G12: 637900 | H12: 7 | I12: 9 | J12: 637900 | K12: 0.0446 | L12: 7.9374
A13: 45973 | B13: 241 | C13: 325 | D13: 78386 | E13: 3 | F13: 3 | G13: 137900 | H13: 3 | I13: 3 | J13: 137900 | K13: 0.0124 | L13: 1.7592
... A31: 45991 | B31: 127 | C31: 330 | D31: 41888 | E31: 3 | F31: 3 | G31: 104400 | H31: 4 | I31: 4 | J31: 163400 | K31: 0.0315 | L31: 3.9009

Sheet 11_매출정리
A1: 날짜 | B1: NO | C1: 주문번호 | D1: 주문순번 | E1: 배송번호 | F1: 주문상태 | G1: 구매자명 | H1: 구매자ID | I1: 결제완료일 | J1: 발송처리일 | K1: 배송완료일 | L1: 수취확인일 | M1: 정산확정일 | N1: 송금완료일 | O1: 상품번호 | P1: 상품명 | Q1: 옵션명 | R1: 수량 | S1: 정산금액 | T1: 판매금액합계 | U1: 추가정산금액합계 | V1: 공제금액합계 | W1: 빠른정산선지급금액 | X1: 판매가 | Y1: 옵션가 | Z1: 선결제배송비 | AA1: 도서산간배송비 | AB1: 구매자부담 반품/교환배송비 | AC1: 반품/교환추가금 | AD1: 반품선결제배송비 | AE1: 반품도서산간배송비 | AF1: 해외취소배송비 | AG1: 티켓예매수수료 | AH1: 티켓취소예매수수료 | AI1: 티켓취소위약금 | AJ1: 여행취소위약금 | AK1: [장산]스토어묶음할인 | AL1: 송장번호 | AM1: 서비스이용료정책 | AN1: 기본서비스이용율 | AO1: 서비스이용료(상품) | AP1: 제휴마케팅대행(상품) | AQ1: 서비스이용료(선결제배송비) | AR1: 제휴마케팅대행(선결제배송비) | AS1: 할인쿠폰이용료 | AT1: 판매자기본할인 | AU1: 판매자추가할인 | AV1: 11번가할인 | AW1: 복수구매할인비용 | AX1: 판매자부담카드추가할인 | AY1: [공제]스토어묶음할인 | AZ1: 포인트이용료 | BA1: 칩이용료 | BB1: 무이자할부이용료 | BC1: 후불광고비 | BD1: 지정택배이용료 | BE1: 전세계배송 판매자책임반품 | BF1: 수출대행수수료 | BG1: 물류이용수수료 | BH1: 반품보험료
A2: =I2 -> 45962 | B2: 1 | C2: 20251101007738962 | D2: 1 | E2: 2647103118 | F2: 구매확정 | G2: 서아름 | H2: kon********* | I2: 45962 | J2: 45964 | K2: 45965 | L2: 45973 | M2: 45973 | N2: 45975 | O2: 8218763311 | P2: 머레이 3in1 맥세이프 보조배터리 애플워치 충전독 일체형 10000mAh 대용량 스마트폰 거치대 | Q2: 색상:블랙-1개 | R2: 1 | S2: 22948 | T2: 29000 | U2: 0 | V2: 6052 | W2: 0 | X2: 29000 | Y2: 0 | Z2: 0 | AA2: 0 | AB2: 0 | AC2: 0 | AD2: 0 | AE2: 0 | AF2: 0 | AG2: 0 | AH2: 0 | AI2: 0 | AJ2: 0 | AK2: 0 | AL2: 460723947880 | AM2: 동의 | AN2: 0.09 | AO2: 0 | AP2: 0 | AQ2: 0 | AR2: 0 | AS2: 5832 | AT2: 2700 | AU2: 3132 | AV2: 598 | AW2: 0 | AX2: 0 | AY2: 0 | AZ2: 0 | BA2: 0 | BB2: 0 | BC2: 220 | BD2: 0 | BE2: 0 | BF2: 0 | BG2: 0 | BH2: 0
A3: =I3 -> 45962 | B3: 2 | C3: 20251101007755765 | D3: 1 | E3: 2647113402 | F3: 구매확정 | G3: 박푸른 | H3: wbd*** | I3: 45962 | J3: 45964 | K3: 45965 | L3: 45973 | M3: 45973 | N3: 45975 | O3: 6342749718 | P3: 머레이 스톤 손난로 보조배터리 10,000mAh 대용량배터리 / KC안전인증 / 3단온도조절 / 양면 급속발열 / LED액정 잔량표시 / 수족냉증 | Q3: 색상:매트 핑크-1개 | R3: 1 | S3: 25109 | T3: 59000 | U3: 0 | V3: 33891 | W3: 25109 | X3: 59000 | Y3: 0 | Z3: 0 | AA3: 0 | AB3: 0 | AC3: 0 | AD3: 0 | AE3: 0 | AF3: 0 | AG3: 0 | AH3: 0 | AI3: 0 | AJ3: 0 | AK3: 0 | AL3: 460723947891 | AM3: 동의 | AN3: 0.09 | AO3: 2038 | AP3: 0 | AQ3: 0 | AR3: 0 | AS3: 31330 | AT3: 27240 | AU3: 4090 | AV3: 0 | AW3: 0 | AX3: 0 | AY3: 0 | AZ3: 0 | BA3: 0 | BB3: 0 | BC3: 523 | BD3: 0 | BE3: 0 | BF3: 0 | BG3: 0 | BH3: 0
A4: =I4 -> 45962 | B4: 3 | C4: 20251101007937558 | D4: 1 | E4: 2647217241 | F4: 구매확정 | G4: name-3719882576 | H4: wpf*** | I4: 45962 | J4: 45964 | K4: 45965 | L4: 45973 | M4: 45973 | N4: 45975 | O4: 3967025462 | P4: 머레이 무선 블루투스 인체공학 버티컬 마우스 BM-550 | Q4: 1개 | R4: 1 | S4: 28780 | T4: 39900 | U4: 0 | V4: 11120 | W4: 0 | X4: 39900 | Y4: 0 | Z4: 0 | AA4: 0 | AB4: 0 | AC4: 0 | AD4: 0 | AE4: 0 | AF4: 0 | AG4: 0 | AH4: 0 | AI4: 0 | AJ4: 0 | AK4: 0 | AL4: 460723947902 | AM4: 동의 | AN4: 0.09 | AO4: 719 | AP4: 0 | AQ4: 0 | AR4: 0 | AS4: 7990 | AT4: 4400 | AU4: 3590 | AV4: 0 | AW4: 0 | AX4: 0 | AY4: 0 | AZ4: 0 | BA4: 0 | BB4: 0 | BC4: 2411 | BD4: 0 | BE4: 0 | BF4: 0 | BG4: 0 | BH4: 0
A5: =I5 -> 45962 | B5: 4 | C5: 20251101007947086 | D5: 1 | E5: 2647222551 | F5: 구매확정 | G5: name-1741642988 | H5: 100******************** | I5: 45962 | J5: 45964 | K5: 45965 | L5: 45973 | M5: 45973 | N5: 45975 | O5: 6422434702 | P5: 머레이 맥세이프 스마트폰 360도 회전 다용도 거치대 (맥세이프링 포함) 차량용 책상용 사무용 강력거치 | Q5: 수량:단품 구매(1개)-1개 | R5: 1 | S5: 15937 | T5: 19900 | U5: 0 | V5: 3963 | W5: 0 | X5: 19900 | Y5: 0 | Z5: 0 | AA5: 0 | AB5: 0 | AC5: 0 | AD5: 0 | AE5: 0 | AF5: 0 | AG5: 0 | AH5: 0 | AI5: 0 | AJ5: 0 | AK5: 0 | AL5: 460723947913 | AM5: 동의 | AN5: 0.11 | AO5: 1557 | AP5: 0 | AQ5: 0 | AR5: 0 | AS5: 1990 | AT5: 1200 | AU5: 790 | AV5: 0 | AW5: 0 | AX5: 0 | AY5: 0 | AZ5: 0 | BA5: 0 | BB5: 0 | BC5: 416 | BD5: 0 | BE5: 0 | BF5: 0 | BG5: 0 | BH5: 0
A6: =I6 -> 45962 | B6: 5 | C6: 20251101008090674 | D6: 3 | E6: 2647318872 | F6: 구매확정 | G6: 박새롬 | H6: 360**************** | I6: 45962 | J6: 45964 | K6: 45965 | L6: 45973 | M6: 45973 | N6: 45975 | O6: 6342749718 | P6: 머레이 스톤 손난로 보조배터리 10,000mAh 대용량배터리 / KC안전인증 / 3단온도조절 / 양면 급속발열 / LED액정 잔량표시 / 수족냉증 | Q6: 색상:매트 핑크-1개 | R6: 1 | S6: 25245 | T6: 59000 | U6: 0 | V6: 33755 | W6: 25245 | X6: 59000 | Y6: 0 | Z6: 0 | AA6: 0 | AB6: 0 | AC6: 0 | AD6: 0 | AE6: 0 | AF6: 0 | AG6: 0 | AH6: 0 | AI6: 0 | AJ6: 0 | AK6: 0 | AL6: 460723947924 | AM6: 동의 | AN6: 0.09 | AO6: 2614 | AP6: 0 | AQ6: 0 | AR6: 0 | AS6: 30610 | AT6: 27240 | AU6: 3370 | AV6: 0 | AW6: 0 | AX6: 0 | AY6: 0 | AZ6: 0 | BA6: 0 | BB6: 0 | BC6: 531 | BD6: 0 | BE6: 0 | BF6: 0 | BG6: 0 | BH6: 0
A7: =I7 -> 45962 | B7: 6 | C7: 20251101008145165 | D7: 1 | E7: 2647355404 | F7: 구매확정 | G7: 강가온 | H7: 423**************** | I7: 45962 | J7: 45964 | K7: 45965 | L7: 45966 | M7: 45966 | N7: 45968 | O7: 6546161396 | P7: 머레이 휴대용 미니 전기면도기 SV-2 학교 여행 회사 출장용 면도기 | Q7: 색상:실버 그레이-1개 | R7: 1 | S7: 13764 | T7: 18000 | U7: 0 | V7: 4236 | W7: 13764 | X7: 18000 | Y7: 0 | Z7: 0 | AA7: 0 | AB7: 0 | AC7: 0 | AD7: 0 | AE7: 0 | AF7: 0 | AG7: 0 | AH7: 0 | AI7: 0 | AJ7: 0 | AK7: 0 | AL7: 460723947935 | AM7: 동의 | AN7: 0.11 | AO7: 1124 | AP7: 0 | AQ7: 0 | AR7: 0 | AS7: 2780 | AT7: 1710 | AU7: 1070 | AV7: 0 | AW7: 0 | AX7: 0 | AY7: 0 | AZ7: 0 | BA7: 0 | BB7: 0 | BC7: 332 | BD7: 0 | BE7: 0 | BF7: 0 | BG7: 0 | BH7: 0
A8: =I8 -> 45962 | B8: 7 | C8: 20251101008234458 | D8: 1 | E8: 2647418877 | F8: 구매확정 | G8: name-336367376 | H8: qnf*** | I8: 45962 | J8: 45964 | K8: 45965 | L8: 45973 | M8: 45973 | N8: 45975 | O8: 6546161396 | P8: 머레이 휴대용 미니 전기면도기 SV-2 학교 여행 회사 출장용 면도기 | Q8: 색상:글리터 그린-1개 | R8: 1 | S8: 13764 | T8: 18000 | U8: 0 | V8: 4236 | W8: 5420 | X8: 18000 | Y8: 0 | Z8: 0 | AA8: 0 | AB8: 0 | AC8: 0 | AD8: 0 | AE8: 0 | AF8: 0 | AG8: 0 | AH8: 0 | AI8: 0 | AJ8: 0 | AK8: 0 | AL8: 460723947946 | AM8: 동의 | AN8: 0.11 | AO8: 1124 | AP8: 0 | AQ8: 0 | AR8: 0 | AS8: 2780 | AT8: 1710 | AU8: 1070 | AV8: 0 | AW8: 0 | AX8: 0 | AY8: 0 | AZ8: 0 | BA8: 0 | BB8: 0 | BC8: 332 | BD8: 0 | BE8: 0 | BF8: 0 | BG8: 0 | BH8: 0
A9: =I9 -> 45963 | B9: 8 | C9: 20251102008313667 | D9: 1 | E9: 2647468827 | F9: 구매확정 | G9: name-1468199151 | H9: gra**** | I9: 45963 | J9: 45964 | K9: 45965 | L9: 45966 | M9: 45966 | N9: 45968 | O9: 4968370224 | P9: 차량용 캐릭터 송풍구 방향제 MK-KUKII 프로펠러 디퓨저 | Q9: 디자인:쿠키 도그 그린 (오션향)-1개 | R9: 1 | S9: 12839 | T9: 20000 | U9: 0 | V9: 7161 | W9: 0 | X9: 20000 | Y9: 0 | Z9: 0 | AA9: 0 | AB9: 0 | AC9: 0 | AD9: 0 | AE9: 0 | AF9: 0 | AG9: 0 | AH9: 0 | AI9: 0 | AJ9: 0 | AK9: 0 | AL9: 460723947950 | AM9: 동의 | AN9: 0.13 | AO9: 1168 | AP9: 0 | AQ9: 0 | AR9: 0 | AS9: 3180 | AT9: 1390 | AU9: 1790 | AV9: 0 | AW9: 1000 | AX9: 0 | AY9: 0 | AZ9: 0 | BA9: 0 | BB9: 0 | BC9: 1813 | BD9: 0 | BE9: 0 | BF9: 0 | BG9: 0 | BH9: 0
A10: =I10 -> 45963 | B10: 9 | C10: 20251102008313667 | D10: 2 | E10: 2647468827 | F10: 구매확정 | G10: name-1468199151 | H10: gra**** | I10: 45963 | J10: 45964 | K10: 45965 | L10: 45966 | M10: 45966 | N10: 45968 | O10: 4968370224 | P10: 차량용 캐릭터 송풍구 방향제 MK-KUKII 프로펠러 디퓨저 | Q10: 디자인:히키 베어 블랙 (바닐라향)-1개 | R10: 1 | S10: 12839 | T10: 20000 | U10: 0 | V10: 7161 | W10: 0 | X10: 20000 | Y10: 0 | Z10: 0 | AA10: 0 | AB10: 0 | AC10: 0 | AD10: 0 | AE10: 0 | AF10: 0 | AG10: 0 | AH10: 0 | AI10: 0 | AJ10: 0 | AK10: 0 | AL10: 460723947950 | AM10: 동의 | AN10: 0.13 | AO10: 1168 | AP10: 0 | AQ10: 0 | AR10: 0 | AS10: 3180 | AT10: 1390 | AU10: 1790 | AV10: 0 | AW10: 1000 | AX10: 0 | AY10: 0 | AZ10: 0 | BA10: 0 | BB10: 0 | BC10: 1813 | BD10: 0 | BE10: 0 | BF10: 0 | BG10: 0 | BH10: 0
A11: =I11 -> 45963 | B11: 10 | C11: 20251102008387489 | D11: 1 | E11: 2647503535 | F11: 구매확정 | G11: 임새롬 | H11: nsh*** | I11: 45963 | J11: 45964 | K11: 45965 | L11: 45973 | M11: 45973 | N11: 45975 | O11: 5370879772 | P11: 원쁠원 머레이 4IN1 미니스탠드 스마트기기 무선충전기 F5 (+25W 고속충전어댑터 세트) 애플워치 갤럭시워치 에어팟 버즈 호환 갤럭시S25 충전기 | Q11: 호환모델/색상:삼성전용/화이트,초고속충전어댑터 색상:화이트-1개 | R11: 1 | S11: 24627 | T11: 33000 | U11: 0 | V11: 8373 | W11: 0 | X11: 33000 | Y11: 0 | Z11: 0 | AA11: 0 | AB11: 0 | AC11: 0 | AD11: 0 | AE11: 0 | AF11: 0 | AG11: 0 | AH11: 0 | AI11: 0 | AJ11: 0 | AK11: 0 | AL11: 460723947972 | AM11: 동의 | AN11: 0.09 | AO11: 0 | AP11: 0 | AQ11: 0 | AR11: 0 | AS11: 6624 | AT11: 3060 | AU11: 3564 | AV11: 406 | AW11: 0 | AX11: 0 | AY11: 0 | AZ11: 0 | BA11: 0 | BB11: 0 | BC11: 1749 | BD11: 0 | BE11: 0 | BF11: 0 | BG11: 0 | BH11: 0
A12: =I12 -> 45963 | B12: 11 | C12: 20251102008498823 | D12: 1 | E12: 2647571791 | F12: 구매확정 | G12: name-506429549 | H12: asy**************** | I12: 45963 | J12: 45964 | K12: 45965 | L12: 45973 | M12: 45973 | N12: 45975 | O12: 6342749718 | P12: 머레이 스톤 손난로 보조배터리 10,000mAh 대용량배터리 / KC안전인증 / 3단온도조절 / 양면 급속발열 / LED액정 잔량표시 / 수족냉증 | Q12: 색상:매트 블랙-1개 | R12: 1 | S12: 22004 | T12: 59000 | U12: 0 | V12: 36996 | W12: 22004 | X12: 59000 | Y12: 0 | Z12: 0 | AA12: 0 | AB12: 0 | AC12: 0 | AD12: 0 | AE12: 0 | AF12: 0 | AG12: 0 | AH12: 0 | AI12: 0 | AJ12: 0 | AK12: 0 | AL12: 460723947994 | AM12: 동의 | AN12: 0.09 | AO12: 2038 | AP12: 0 | AQ12: 0 | AR12: 0 | AS12: 33330 | AT12: 29240 | AU12: 4090 | AV12: 0 | AW12: 0 | AX12: 0 | AY12: 0 | AZ12: 0 | BA12: 0 | BB12: 0 | BC12: 1628 | BD12: 0 | BE12: 0 | BF12: 0 | BG12: 0 | BH12: 0
A13: =I13 -> 45963 | B13: 12 | C13: 20251102008536442 | D13: 1 | E13: 2647599688 | F13: 구매확정 | G13: 임한별 | H13: lif************************* | I13: 45963 | J13: 45964 | K13: 45965 | L13: 45967 | M13: 45967 | N13: 45971 | O13: 6546161396 | P13: 머레이 휴대용 미니 전기면도기 SV-2 학교 여행 회사 출장용 면도기 | Q13: 색상:글리터 그린-1개 | R13: 1 | S13: 12937 | T13: 18000 | U13: 0 | V13: 5063 | W13: 12937 | X13: 18000 | Y13: 0 | Z13: 0 | AA13: 0 | AB13: 0 | AC13: 0 | AD13: 0 | AE13: 0 | AF13: 0 | AG13: 0 | AH13: 0 | AI13: 0 | AJ13: 0 | AK13: 0 | AL13: 460723948005 | AM13: 동의 | AN13: 0.11 | AO13: 1124 | AP13: 0 | AQ13: 0 | AR13: 0 | AS13: 2780 | AT13: 1710 | AU13: 1070 | AV13: 0 | AW13: 0 | AX13: 0 | AY13: 0 | AZ13: 0 | BA13: 0 | BB13: 0 | BC13: 1159 | BD13: 0 | BE13: 0 | BF13: 0 | BG13: 0 | BH13: 0
... A35: =I35 -> 45965 | B35: 34 | C35: 20251104009729625 | D35: 1 | E35: 2648592446 | F35: 구매확정 | G35: name-512718668 | H35: ape***** | I35: 45965 | J35: 45965 | K35: 45966 | L35: 45967 | M35: 45967 | N35: 45971 | O35: 7175614365 | P35: 머레이 2세대 볼펜형 코털/잔털정리기 GR-PEN 트리머기기 코털제거기 눈썹정리 | Q35: 1개 | R35: 1 | S35: 12520 | T35: 15000 | U35: 0 | V35: 2480 | W35: 0 | X35: 15000 | Y35: 0 | Z35: 0 | AA35: 0 | AB35: 0 | AC35: 0 | AD35: 0 | AE35: 0 | AF35: 0 | AG35: 0 | AH35: 0 | AI35: 0 | AJ35: 0 | AK35: 0 | AL35: 460747987501 | AM35: 동의 | AN35: 0.09 | AO35: 870 | AP35: 0 | AQ35: 0 | AR35: 0 | AS35: 1500 | AT35: 900 | AU35: 600 | AV35: 0 | AW35: 0 | AX35: 0 | AY35: 0 | AZ35: 0 | BA35: 0 | BB35: 0 | BC35: 110 | BD35: 0 | BE35: 0 | BF35: 0 | BG35: 0 | BH35: 0
A36: =I36 -> 45965 | B36: 35 | C36: 2.0251104e+16 | D36: 2 | E36: 2648670646 | F36: 구매확정 | G36: name-1214061277 | H36: gan******* | I36: 45965 | J36: 45965 | K36: 45966 | L36: 45974 | M36: 45974 | N36: 45978 | O36: 6342749718 | P36: 머레이 스톤 손난로 보조배터리 10,000mAh 대용량배터리 / KC안전인증 / 3단온도조절 / 양면 급속발열 / LED액정 잔량표시 / 수족냉증 | Q36: 색상:매트 그린-9개 | R36: 9 | S36: 213306 | T36: 531000 | U36: 0 | V36: 317694 | W36: 0 | X36: 531000 | Y36: 0 | Z36: 0 | AA36: 0 | AB36: 0 | AC36: 0 | AD36: 0 | AE36: 0 | AF36: 0 | AG36: 0 | AH36: 0 | AI36: 0 | AJ36: 0 | AK36: 0 | AL36: 460748123334 | AM36: 동의 | AN36: 0.09 | AO36: 32734 | AP36: 0 | AQ36: 0 | AR36: 0 | AS36: 265970 | AT36: 247150 | AU36: 18820 | AV36: 0 | AW36: 18000 | AX36: 0 | AY36: 0 | AZ36: 0 | BA36: 0 | BB36: 0 | BC36: 990 | BD36: 0 | BE36: 0 | BF36: 0 | BG36: 0 | BH36: 0
A37: =I37 -> 45965 | B37: 36 | C37: 2.0251104e+16 | D37: 1 | E37: 2648670646 | F37: 구매확정 | G37: name-1214061277 | H37: gan******* | I37: 45965 | J37: 45965 | K37: 45966 | L37: 45974 | M37: 45974 | N37: 45978 | O37: 6342749718 | P37: 머레이 스톤 손난로 보조배터리 10,000mAh 대용량배터리 / KC안전인증 / 3단온도조절 / 양면 급속발열 / LED액정 잔량표시 / 수족냉증 | Q37: 색상:매트 블랙-10개 | R37: 10 | S37: 237236 | T37: 590000 | U37: 0 | V37: 352764 | W37: 226892 | X37: 590000 | Y37: 0 | Z37: 0 | AA37: 0 | AB37: 0 | AC37: 0 | AD37: 0 | AE37: 0 | AF37: 0 | AG37: 0 | AH37: 0 | AI37: 0 | AJ37: 0 | AK37: 0 | AL37: 460748123334 | AM37: 동의 | AN37: 0.09 | AO37: 36364 | AP37: 0 | AQ37: 0 | AR37: 0 | AS37: 295300 | AT37: 274380 | AU37: 20920 | AV37: 0 | AW37: 20000 | AX37: 0 | AY37: 0 | AZ37: 0 | BA37: 0 | BB37: 0 | BC37: 1100 | BD37: 0 | BE37: 0 | BF37: 0 | BG37: 0 | BH37: 0
A38: =I38 -> 45965 | B38: 37 | C38: 20251104009842476 | D38: 1 | E38: 2648707796 | F38: 구매확정 | G38: name-1681264304 | H38: han***** | I38: 45965 | J38: 45966 | K38: 45967 | L38: 45975 | M38: 45975 | N38: 45979 | O38: 6363337566 | P38: 머레이 절전형 발열 파티션 워머 LY-PH4 사무실 책상 발난로 히팅패드 전기히터온풍기 전기담요 | Q38: 1개 | R38: 1 | S38: 37646 | T38: 48000 | U38: 0 | V38: 10354 | W38: 0 | X38: 48000 | Y38: 0 | Z38: 0 | AA38: 0 | AB38: 0 | AC38: 0 | AD38: 0 | AE38: 0 | AF38: 0 | AG38: 0 | AH38: 0 | AI38: 0 | AJ38: 0 | AK38: 0 | AL38: 460752249624 | AM38: 동의 | AN38: 0.09 | AO38: 2792 | AP38: 0 | AQ38: 0 | AR38: 0 | AS38: 6890 | AT38: 4980 | AU38: 1910 | AV38: 0 | AW38: 0 | AX38: 0 | AY38: 0 | AZ38: 0 | BA38: 0 | BB38: 0 | BC38: 672 | BD38: 0 | BE38: 0 | BF38: 0 | BG38: 0 | BH38: 0
A39: =I39 -> 45965 | B39: 38 | C39: 20251104009994792 | D39: 1 | E39: 2648829959 | F39: 구매확정 | G39: 정하늘 | H39: mnb***** | I39: 45965 | J39: 45966 | K39: 45967 | L39: 45975 | M39: 45975 | N39: 45979 | O39: 6342749718 | P39: 머레이 스톤 손난로 보조배터리 10,000mAh 대용량배터리 / KC안전인증 / 3단온도조절 / 양면 급속발열 / LED액정 잔량표시 / 수족냉증 | Q39: 색상:매트 블랙-1개 | R39: 1 | S39: 21592 | T39: 59000 | U39: 0 | V39: 37408 | W39: 21592 | X39: 59000 | Y39: 0 | Z39: 0 | AA39: 0 | AB39: 0 | AC39: 0 | AD39: 0 | AE39: 0 | AF39: 0 | AG39: 0 | AH39: 0 | AI39: 0 | AJ39: 0 | AK39: 0 | AL39: 460752249635 | AM39: 동의 | AN39: 0.09 | AO39: 2438 | AP39: 0 | AQ39: 0 | AR39: 0 | AS39: 30830 | AT39: 27240 | AU39: 3590 | AV39: 0 | AW39: 2000 | AX39: 0 | AY39: 0 | AZ39: 0 | BA39: 0 | BB39: 0 | BC39: 2140 | BD39: 0 | BE39: 0 | BF39: 0 | BG39: 0 | BH39: 0
A40: =I40 -> 45965 | B40: 39 | C40: 20251104009994792 | D40: 2 | E40: 2648829959 | F40: 구매확정 | G40: 정하늘 | H40: mnb***** | I40: 45965 | J40: 45966 | K40: 45967 | L40: 45975 | M40: 45975 | N40: 45979 | O40: 6342749718 | P40: 머레이 스톤 손난로 보조배터리 10,000mAh 대용량배터리 / KC안전인증 / 3단온도조절 / 양면 급속발열 / LED액정 잔량표시 / 수족냉증 | Q40: 색상:매트 그린-1개 | R40: 1 | S40: 21592 | T40: 59000 | U40: 0 | V40: 37408 | W40: 21592 | X40: 59000 | Y40: 0 | Z40: 0 | AA40: 0 | AB40: 0 | AC40: 0 | AD40: 0 | AE40: 0 | AF40: 0 | AG40: 0 | AH40: 0 | AI40: 0 | AJ40: 0 | AK40: 0 | AL40: 460752249635 | AM40: 동의 | AN40: 0.09 | AO40: 2438 | AP40: 0 | AQ40: 0 | AR40: 0 | AS40: 30830 | AT40: 27240 | AU40: 3590 | AV40: 0 | AW40: 2000 | AX40: 0 | AY40: 0 | AZ40: 0 | BA40: 0 | BB40: 0 | BC40: 2140 | BD40: 0 | BE40: 0 | BF40: 0 | BG40: 0 | BH40: 0
A41: =I41 -> 45966 | B41: 40 | C41: 20251105010285964 | D41: 1 | E41: 2649056274 | F41: 구매확정 | G41: name-3339452678 | H41: ljj*** | I41: 45966 | J41: 45966 | K41: 45967 | L41: 45967 | M41: 45967 | N41: 45971 | O41: 6546161396 | P41: 머레이 휴대용 미니 전기면도기 SV-2 학교 여행 회사 출장용 면도기 | Q41: 색상:글리터 그린-1개 | R41: 1 | S41: 13764 | T41: 18000 | U41: 0 | V41: 4236 | W41: 13764 | X41: 18000 | Y41: 0 | Z41: 0 | AA41: 0 | AB41: 0 | AC41: 0 | AD41: 0 | AE41: 0 | AF41: 0 | AG41: 0 | AH41: 0 | AI41: 0 | AJ41: 0 | AK41: 0 | AL41: 460757489850 | AM41: 동의 | AN41: 0.11 | AO41: 1124 | AP41: 0 | AQ41: 0 | AR41: 0 | AS41: 2780 | AT41: 1710 | AU41: 1070 | AV41: 0 | AW41: 0 | AX41: 0 | AY41: 0 | AZ41: 0 | BA41: 0 | BB41: 0 | BC41: 332 | BD41: 0 | BE41: 0 | BF41: 0 | BG41: 0 | BH41: 0
A42: =I42 -> 45966 | B42: 41 | C42: 20251105010305467 | D42: 1 | E42: 2649070793 | F42: 구매확정 | G42: 신새롬 | H42: syh**** | I42: 45966 | J42: 45966 | K42: 45967 | L42: 45975 | M42: 45975 | N42: 45979 | O42: 7175614365 | P42: 머레이 2세대 볼펜형 코털/잔털정리기 GR-PEN 트리머기기 코털제거기 눈썹정리 | Q42: 1개 | R42: 1 | S42: 11602 | T42: 15000 | U42: 0 | V42: 3398 | W42: 0 | X42: 15000 | Y42: 0 | Z42: 0 | AA42: 0 | AB42: 0 | AC42: 0 | AD42: 0 | AE42: 0 | AF42: 0 | AG42: 0 | AH42: 0 | AI42: 0 | AJ42: 0 | AK42: 0 | AL42: 460757489861 | AM42: 동의 | AN42: 0.09 | AO42: 870 | AP42: 0 | AQ42: 0 | AR42: 0 | AS42: 1500 | AT42: 900 | AU42: 600 | AV42: 0 | AW42: 0 | AX42: 0 | AY42: 0 | AZ42: 0 | BA42: 0 | BB42: 0 | BC42: 1028 | BD42: 0 | BE42: 0 | BF42: 0 | BG42: 0 | BH42: 0
A43: =I43 -> 45966 | B43: 42 | C43: 20251105010330019 | D43: 1 | E43: 2649094298 | F43: 구매확정 | G43: name-2419070241 | H43: yhs**** | I43: 45966 | J43: 45966 | K43: 45967 | L43: 45975 | M43: 45975 | N43: 45979 | O43: 7175614365 | P43: 머레이 2세대 볼펜형 코털/잔털정리기 GR-PEN 트리머기기 코털제거기 눈썹정리 | Q43: 1개 | R43: 1 | S43: 11783 | T43: 15000 | U43: 0 | V43: 3217 | W43: 0 | X43: 15000 | Y43: 0 | Z43: 0 | AA43: 0 | AB43: 0 | AC43: 0 | AD43: 0 | AE43: 0 | AF43: 0 | AG43: 0 | AH43: 0 | AI43: 0 | AJ43: 0 | AK43: 0 | AL43: 460757489872 | AM43: 동의 | AN43: 0.09 | AO43: 870 | AP43: 0 | AQ43: 0 | AR43: 0 | AS43: 1500 | AT43: 900 | AU43: 600 | AV43: 0 | AW43: 0 | AX43: 0 | AY43: 0 | AZ43: 0 | BA43: 0 | BB43: 0 | BC43: 847 | BD43: 0 | BE43: 0 | BF43: 0 | BG43: 0 | BH43: 0
A44: =I44 -> 45966 | B44: 43 | C44: 20251105010331354 | D44: 1 | E44: 2649095470 | F44: 구매확정 | G44: name-4033053505 | H44: kai**** | I44: 45966 | J44: 45966 | K44: 45967 | L44: 45975 | M44: 45975 | N44: 45979 | O44: 5370879772 | P44: 원쁠원 머레이 4IN1 미니스탠드 스마트기기 무선충전기 F5 (+25W 고속충전어댑터 세트) 애플워치 갤럭시워치 에어팟 버즈 호환 갤럭시S25 충전기 | Q44: 호환모델/색상:삼성전용/블랙,초고속충전어댑터 색상:블랙-1개 | R44: 1 | S44: 24356 | T44: 33000 | U44: 0 | V44: 8644 | W44: 0 | X44: 33000 | Y44: 0 | Z44: 0 | AA44: 0 | AB44: 0 | AC44: 0 | AD44: 0 | AE44: 0 | AF44: 0 | AG44: 0 | AH44: 0 | AI44: 0 | AJ44: 0 | AK44: 0 | AL44: 460757489883 | AM44: 동의 | AN44: 0.09 | AO44: 1394 | AP44: 0 | AQ44: 0 | AR44: 0 | AS44: 7030 | AT44: 5060 | AU44: 1970 | AV44: 0 | AW44: 0 | AX44: 0 | AY44: 0 | AZ44: 0 | BA44: 0 | BB44: 0 | BC44: 220 | BD44: 0 | BE44: 0 | BF44: 0 | BG44: 0 | BH44: 0
A45: =I45 -> 45966 | B45: 44 | C45: 20251105010454202 | D45: 1 | E45: 2649202103 | F45: 구매확정 | G45: name-3853291241 | H45: agn**** | I45: 45966 | J45: 45967 | K45: 45968 | L45: 45976 | M45: 45976 | N45: 45979 | O45: 5466907344 | P45: 머레이 필수템 레인보우LED 블루투스 스피커 노래방기기 듀얼마이크 수업용 가정용 스피커 (가족/학교/여행/MT/야유회/학예회/캠핑 핫템) +LED미러볼 세트 | Q45: 색상 선택:블랙-1개 | R45: 1 | S45: 55898 | T45: 70000 | U45: 0 | V45: 14102 | W45: 55898 | X45: 70000 | Y45: 0 | Z45: 0 | AA45: 0 | AB45: 0 | AC45: 0 | AD45: 0 | AE45: 0 | AF45: 0 | AG45: 0 | AH45: 0 | AI45: 0 | AJ45: 0 | AK45: 0 | AL45: 460762812532 | AM45: 동의 | AN45: 0.09 | AO45: 4092 | AP45: 0 | AQ45: 0 | AR45: 0 | AS45: 9900 | AT45: 7140 | AU45: 2760 | AV45: 0 | AW45: 0 | AX45: 0 | AY45: 0 | AZ45: 0 | BA45: 0 | BB45: 0 | BC45: 110 | BD45: 0 | BE45: 0 | BF45: 0 | BG45: 0 | BH45: 0
A46: =I46 -> 45966 | B46: 45 | C46: 20251105010539035 | D46: 1 | E46: 2649266997 | F46: 구매확정 | G46: 정슬기 | H46: oxy****** | I46: 45966 | J46: 45967 | K46: 45968 | L46: 45976 | M46: 45976 | N46: 45979 | O46: 3967025462 | P46: 머레이 무선 블루투스 인체공학 버티컬 마우스 BM-550 | Q46: 1개 | R46: 1 | S46: 28780 | T46: 39900 | U46: 0 | V46: 11120 | W46: 0 | X46: 39900 | Y46: 0 | Z46: 0 | AA46: 0 | AB46: 0 | AC46: 0 | AD46: 0 | AE46: 0 | AF46: 0 | AG46: 0 | AH46: 0 | AI46: 0 | AJ46: 0 | AK46: 0 | AL46: 460762812543 | AM46: 동의 | AN46: 0.09 | AO46: 719 | AP46: 0 | AQ46: 0 | AR46: 0 | AS46: 7990 | AT46: 4400 | AU46: 3590 | AV46: 0 | AW46: 0 | AX46: 0 | AY46: 0 | AZ46: 0 | BA46: 0 | BB46: 0 | BC46: 2411 | BD46: 0 | BE46: 0 | BF46: 0 | BG46: 0 | BH46: 0
A47: =I47 -> 45967 | B47: 46 | C47: 20251106010652569 | D47: 1 | E47: 2649348420 | F47: 구매확정 | G47: name-3801936706 | H47: egl***** | I47: 45967 | J47: 45967 | K47: 45968 | L47: 45968 | M47: 45968 | N47: 45972 | O47: 5924859476 | P47: 머레이 LED알람시계 4in1 맥세이프 고속무선충전기 갤럭시워치 올인원충전기+맥세이프링 세트 | Q47: 색상:시크 블랙-1개 | R47: 1 | S47: 25354 | T47: 32000 | U47: 0 | V47: 6646 | W47: 0 | X47: 32000 | Y47: 0 | Z47: 0 | AA47: 0 | AB47: 0 | AC47: 0 | AD47: 0 | AE47: 0 | AF47: 0 | AG47: 0 | AH47: 0 | AI47: 0 | AJ47: 0 | AK47: 0 | AL47: 460762812565 | AM47: 동의 | AN47: 0.09 | AO47: 0 | AP47: 0 | AQ47: 0 | AR47: 0 | AS47: 6426 | AT47: 2970 | AU47: 3456 | AV47: 454 | AW47: 0 | AX47: 0 | AY47: 0 | AZ47: 0 | BA47: 0 | BB47: 0 | BC47: 220 | BD47: 0 | BE47: 0 | BF47: 0 | BG47: 0 | BH47: 0
A48: =I48 -> 45967 | B48: 47 | C48: 20251106010653775 | D48: 1 | E48: 2649349323 | F48: 구매확정 | G48: name-117823074 | H48: sdj**** | I48: 45967 | J48: 45967 | K48: 45968 | L48: 45976 | M48: 45976 | N48: 45979 | O48: 2786546082 | P48: 머레이 자동차 HUD 속도계 M-8 차량용 유리창 속도계 헤드업디스플레이 | Q48: 1개 | R48: 1 | S48: 21092 | T48: 29500 | U48: 0 | V48: 8408 | W48: 21092 | X48: 29500 | Y48: 0 | Z48: 0 | AA48: 0 | AB48: 0 | AC48: 0 | AD48: 0 | AE48: 0 | AF48: 0 | AG48: 0 | AH48: 0 | AI48: 0 | AJ48: 0 | AK48: 0 | AL48: 460762812576 | AM48: 동의 | AN48: 0.09 | AO48: 6 | AP48: 0 | AQ48: 0 | AR48: 0 | AS48: 6950 | AT48: 3770 | AU48: 3180 | AV48: 0 | AW48: 0 | AX48: 0 | AY48: 0 | AZ48: 0 | BA48: 0 | BB48: 0 | BC48: 1452 | BD48: 0 | BE48: 0 | BF48: 0 | BG48: 0 | BH48: 0
A49: =I49 -> 45967 | B49: 48 | C49: 20251106010955933 | D49: 2 | E49: 2649608345 | F49: 구매확정 | G49: 한누리 | H49: lun******* | I49: 45967 | J49: 45968 | K49: 45969 | L49: 45971 | M49: 45971 | N49: 45973 | O49: 6031873213 | P49: MURRAY 스마트 미니 차량용 공기청정기 PQ-200 흡연자 필수템 | Q49: 모델명/품번:로즈 골드-1개 | R49: 1 | S49: 21469 | T49: 30000 | U49: 0 | V49: 8531 | W49: 0 | X49: 30000 | Y49: 0 | Z49: 0 | AA49: 0 | AB49: 0 | AC49: 0 | AD49: 0 | AE49: 0 | AF49: 0 | AG49: 0 | AH49: 0 | AI49: 0 | AJ49: 0 | AK49: 0 | AL49: 460772357651 | AM49: 동의 | AN49: 0.13 | AO49: 2948 | AP49: 0 | AQ49: 0 | AR49: 0 | AS49: 5090 | AT49: 3900 | AU49: 1190 | AV49: 0 | AW49: 0 | AX49: 0 | AY49: 0 | AZ49: 0 | BA49: 0 | BB49: 0 | BC49: 493 | BD49: 0 | BE49: 0 | BF49: 0 | BG49: 0 | BH49: 0
... A62: =I62 -> 45970 | B62: 61 | C62: 20251109012137184 | D62: 1 | E62: 2650458895 | F62: 구매확정 | G62: name-1797936151 | H62: dra***** | I62: 45970 | J62: 45971 | K62: 45972 | L62: 45972 | M62: 45972 | N62: 45974 | O62: 7996735307 | P62: 머레이 2세대 강력 코털/잔털정리기 ZP-10 트리머기기 생활방수 코털제거기 눈썹정리 | Q62: 색상:블랙-1개 | R62: 1 | S62: 11333 | T62: 15000 | U62: 0 | V62: 3667 | W62: 11333 | X62: 15000 | Y62: 0 | Z62: 0 | AA62: 0 | AB62: 0 | AC62: 0 | AD62: 0 | AE62: 0 | AF62: 0 | AG62: 0 | AH62: 0 | AI62: 0 | AJ62: 0 | AK62: 0 | AL62: 460786489391 | AM62: 동의 | AN62: 0.09 | AO62: 870 | AP62: 0 | AQ62: 0 | AR62: 0 | AS62: 1500 | AT62: 900 | AU62: 600 | AV62: 0 | AW62: 0 | AX62: 0 | AY62: 0 | AZ62: 0 | BA62: 0 | BB62: 0 | BC62: 1297 | BD62: 0 | BE62: 0 | BF62: 0 | BG62: 0 | BH62: 0
